Workbook

Sheet BUSCAR
B2: BUSCADOR DE CLIENTES | J2: =IF(OR($C$8="",$C$8="(sin filtro)"),FALSE,IF(AND($C$9="",$E$9=""),FALSE,TRUE))
B3: Escriba cualquier parte del nombre, apellido, DPI, licencia, telefono, NIT o "facturar a". | J3: =IF($C$9="",1,$C$9)
J4: =IF($E$9="",2958465,$E$9)
B5: Buscar: | J5: =TRIM(MID(SUBSTITUTE($J$11," ",REPT(" ",99)),1,99))
C6: Puede escribir nombre y apellido en cualquier orden, y sin acentos. Vacio = todos. | J6: =TRIM(MID(SUBSTITUTE($J$11," ",REPT(" ",99)),100,99))
B8: Filtrar por fecha: | C8: (sin filtro) | J8: =TRIM(MID(SUBSTITUTE($J$11," ",REPT(" ",99)),199,99))
B9: Desde: | D9: Hasta: | J9: =TRIM(MID(SUBSTITUTE($J$11," ",REPT(" ",99)),298,99))
B11: Resultados: | C11: =MAX(CLIENTES!$AH$3:$AH$2002)&" cliente(s)" | J11: =SUBSTITUTE(SUBSTITUTE(SUBSTITUTE(SUBSTITUTE(SUBSTITUTE(SUBSTITUTE(SUBSTITUTE(UPPER(TRIM($C$5)),"Á","A"),"É","E"),"Í","I"),"Ó","O"),"Ú","U"),"Ü","U"),"Ñ","N")
B13: CODIGO | C13: APELLIDOS | D13: NOMBRES | E13: DPI / PASAPORTE | F13: LICENCIA | G13: TELEFONO | H13: =IF(OR($C$8="",$C$8="(sin filtro)"),"FECHA",$C$8)
B14: =IF($J14="","",INDEX(CLIENTES!$A$3:$A$3002,$J14)) | C14: =IF($J14="","",TRIM(INDEX(CLIENTES!$B$3:$B$3002,$J14)&" "&INDEX(CLIENTES!$C$3:$C$3002,$J14))) | D14: =IF($J14="","",TRIM(INDEX(CLIENTES!$D$3:$D$3002,$J14)&" "&INDEX(CLIENTES!$E$3:$E$3002,$J14))) | E14: =IF($J14="","",INDEX(CLIENTES!$H$3:$H$3002,$J14)) | F14: =IF($J14="","",INDEX(CLIENTES!$K$3:$K$3002,$J14)) | G14: =IF($J14="","",INDEX(CLIENTES!$R$3:$R$3002,$J14)) | H14: =IF($J14="","",IF(N(INDEX(CLIENTES!$AF$3:$AF$3002,$J14))=0,"",INDEX(CLIENTES!$AF$3:$AF$3002,$J14))) | J14: =IFERROR(MATCH(ROW()-13,CLIENTES!$AH$3:$AH$2002,0),"")
B15: =IF($J15="","",INDEX(CLIENTES!$A$3:$A$3002,$J15)) | C15: =IF($J15="","",TRIM(INDEX(CLIENTES!$B$3:$B$3002,$J15)&" "&INDEX(CLIENTES!$C$3:$C$3002,$J15))) | D15: =IF($J15="","",TRIM(INDEX(CLIENTES!$D$3:$D$3002,$J15)&" "&INDEX(CLIENTES!$E$3:$E$3002,$J15))) | E15: =IF($J15="","",INDEX(CLIENTES!$H$3:$H$3002,$J15)) | F15: =IF($J15="","",INDEX(CLIENTES!$K$3:$K$3002,$J15)) | G15: =IF($J15="","",INDEX(CLIENTES!$R$3:$R$3002,$J15)) | H15: =IF($J15="","",IF(N(INDEX(CLIENTES!$AF$3:$AF$3002,$J15))=0,"",INDEX(CLIENTES!$AF$3:$AF$3002,$J15))) | J15: =IFERROR(MATCH(ROW()-13,CLIENTES!$AH$3:$AH$2002,0),"")
B16: =IF($J16="","",INDEX(CLIENTES!$A$3:$A$3002,$J16)) | C16: =IF($J16="","",TRIM(INDEX(CLIENTES!$B$3:$B$3002,$J16)&" "&INDEX(CLIENTES!$C$3:$C$3002,$J16))) | D16: =IF($J16="","",TRIM(INDEX(CLIENTES!$D$3:$D$3002,$J16)&" "&INDEX(CLIENTES!$E$3:$E$3002,$J16))) | E16: =IF($J16="","",INDEX(CLIENTES!$H$3:$H$3002,$J16)) | F16: =IF($J16="","",INDEX(CLIENTES!$K$3:$K$3002,$J16)) | G16: =IF($J16="","",INDEX(CLIENTES!$R$3:$R$3002,$J16)) | H16: =IF($J16="","",IF(N(INDEX(CLIENTES!$AF$3:$AF$3002,$J16))=0,"",INDEX(CLIENTES!$AF$3:$AF$3002,$J16))) | J16: =IFERROR(MATCH(ROW()-13,CLIENTES!$AH$3:$AH$2002,0),"")
B17: =IF($J17="","",INDEX(CLIENTES!$A$3:$A$3002,$J17)) | C17: =IF($J17="","",TRIM(INDEX(CLIENTES!$B$3:$B$3002,$J17)&" "&INDEX(CLIENTES!$C$3:$C$3002,$J17))) | D17: =IF($J17="","",TRIM(INDEX(CLIENTES!$D$3:$D$3002,$J17)&" "&INDEX(CLIENTES!$E$3:$E$3002,$J17))) | E17: =IF($J17="","",INDEX(CLIENTES!$H$3:$H$3002,$J17)) | F17: =IF($J17="","",INDEX(CLIENTES!$K$3:$K$3002,$J17)) | G17: =IF($J17="","",INDEX(CLIENTES!$R$3:$R$3002,$J17)) | H17: =IF($J17="","",IF(N(INDEX(CLIENTES!$AF$3:$AF$3002,$J17))=0,"",INDEX(CLIENTES!$AF$3:$AF$3002,$J17))) | J17: =IFERROR(MATCH(ROW()-13,CLIENTES!$AH$3:$AH$2002,0),"")
B18: =IF($J18="","",INDEX(CLIENTES!$A$3:$A$3002,$J18)) | C18: =IF($J18="","",TRIM(INDEX(CLIENTES!$B$3:$B$3002,$J18)&" "&INDEX(CLIENTES!$C$3:$C$3002,$J18))) | D18: =IF($J18="","",TRIM(INDEX(CLIENTES!$D$3:$D$3002,$J18)&" "&INDEX(CLIENTES!$E$3:$E$3002,$J18))) | E18: =IF($J18="","",INDEX(CLIENTES!$H$3:$H$3002,$J18)) | F18: =IF($J18="","",INDEX(CLIENTES!$K$3:$K$3002,$J18)) | G18: =IF($J18="","",INDEX(CLIENTES!$R$3:$R$3002,$J18)) | H18: =IF($J18="","",IF(N(INDEX(CLIENTES!$AF$3:$AF$3002,$J18))=0,"",INDEX(CLIENTES!$AF$3:$AF$3002,$J18))) | J18: =IFERROR(MATCH(ROW()-13,CLIENTES!$AH$3:$AH$2002,0),"")
B19: =IF($J19="","",INDEX(CLIENTES!$A$3:$A$3002,$J19)) | C19: =IF($J19="","",TRIM(INDEX(CLIENTES!$B$3:$B$3002,$J19)&" "&INDEX(CLIENTES!$C$3:$C$3002,$J19))) | D19: =IF($J19="","",TRIM(INDEX(CLIENTES!$D$3:$D$3002,$J19)&" "&INDEX(CLIENTES!$E$3:$E$3002,$J19))) | E19: =IF($J19="","",INDEX(CLIENTES!$H$3:$H$3002,$J19)) | F19: =IF($J19="","",INDEX(CLIENTES!$K$3:$K$3002,$J19)) | G19: =IF($J19="","",INDEX(CLIENTES!$R$3:$R$3002,$J19)) | H19: =IF($J19="","",IF(N(INDEX(CLIENTES!$AF$3:$AF$3002,$J19))=0,"",INDEX(CLIENTES!$AF$3:$AF$3002,$J19))) | J19: =IFERROR(MATCH(ROW()-13,CLIENTES!$AH$3:$AH$2002,0),"")
B20: =IF($J20="","",INDEX(CLIENTES!$A$3:$A$3002,$J20)) | C20: =IF($J20="","",TRIM(INDEX(CLIENTES!$B$3:$B$3002,$J20)&" "&INDEX(CLIENTES!$C$3:$C$3002,$J20))) | D20: =IF($J20="","",TRIM(INDEX(CLIENTES!$D$3:$D$3002,$J20)&" "&INDEX(CLIENTES!$E$3:$E$3002,$J20))) | E20: =IF($J20="","",INDEX(CLIENTES!$H$3:$H$3002,$J20)) | F20: =IF($J20="","",INDEX(CLIENTES!$K$3:$K$3002,$J20)) | G20: =IF($J20="","",INDEX(CLIENTES!$R$3:$R$3002,$J20)) | H20: =IF($J20="","",IF(N(INDEX(CLIENTES!$AF$3:$AF$3002,$J20))=0,"",INDEX(CLIENTES!$AF$3:$AF$3002,$J20))) | J20: =IFERROR(MATCH(ROW()-13,CLIENTES!$AH$3:$AH$2002,0),"")
B21: =IF($J21="","",INDEX(CLIENTES!$A$3:$A$3002,$J21)) | C21: =IF($J21="","",TRIM(INDEX(CLIENTES!$B$3:$B$3002,$J21)&" "&INDEX(CLIENTES!$C$3:$C$3002,$J21))) | D21: =IF($J21="","",TRIM(INDEX(CLIENTES!$D$3:$D$3002,$J21)&" "&INDEX(CLIENTES!$E$3:$E$3002,$J21))) | E21: =IF($J21="","",INDEX(CLIENTES!$H$3:$H$3002,$J21)) | F21: =IF($J21="","",INDEX(CLIENTES!$K$3:$K$3002,$J21)) | G21: =IF($J21="","",INDEX(CLIENTES!$R$3:$R$3002,$J21)) | H21: =IF($J21="","",IF(N(INDEX(CLIENTES!$AF$3:$AF$3002,$J21))=0,"",INDEX(CLIENTES!$AF$3:$AF$3002,$J21))) | J21: =IFERROR(MATCH(ROW()-13,CLIENTES!$AH$3:$AH$2002,0),"")
B22: =IF($J22="","",INDEX(CLIENTES!$A$3:$A$3002,$J22)) | C22: =IF($J22="","",TRIM(INDEX(CLIENTES!$B$3:$B$3002,$J22)&" "&INDEX(CLIENTES!$C$3:$C$3002,$J22))) | D22: =IF($J22="","",TRIM(INDEX(CLIENTES!$D$3:$D$3002,$J22)&" "&INDEX(CLIENTES!$E$3:$E$3002,$J22))) | E22: =IF($J22="","",INDEX(CLIENTES!$H$3:$H$3002,$J22)) | F22: =IF($J22="","",INDEX(CLIENTES!$K$3:$K$3002,$J22)) | G22: =IF($J22="","",INDEX(CLIENTES!$R$3:$R$3002,$J22)) | H22: =IF($J22="","",IF(N(INDEX(CLIENTES!$AF$3:$AF$3002,$J22))=0,"",INDEX(CLIENTES!$AF$3:$AF$3002,$J22))) | J22: =IFERROR(MATCH(ROW()-13,CLIENTES!$AH$3:$AH$2002,0),"")
B23: =IF($J23="","",INDEX(CLIENTES!$A$3:$A$3002,$J23)) | C23: =IF($J23="","",TRIM(INDEX(CLIENTES!$B$3:$B$3002,$J23)&" "&INDEX(CLIENTES!$C$3:$C$3002,$J23))) | D23: =IF($J23="","",TRIM(INDEX(CLIENTES!$D$3:$D$3002,$J23)&" "&INDEX(CLIENTES!$E$3:$E$3002,$J23))) | E23: =IF($J23="","",INDEX(CLIENTES!$H$3:$H$3002,$J23)) | F23: =IF($J23="","",INDEX(CLIENTES!$K$3:$K$3002,$J23)) | G23: =IF($J23="","",INDEX(CLIENTES!$R$3:$R$3002,$J23)) | H23: =IF($J23="","",IF(N(INDEX(CLIENTES!$AF$3:$AF$3002,$J23))=0,"",INDEX(CLIENTES!$AF$3:$AF$3002,$J23))) | J23: =IFERROR(MATCH(ROW()-13,CLIENTES!$AH$3:$AH$2002,0),"")
B24: =IF($J24="","",INDEX(CLIENTES!$A$3:$A$3002,$J24)) | C24: =IF($J24="","",TRIM(INDEX(CLIENTES!$B$3:$B$3002,$J24)&" "&INDEX(CLIENTES!$C$3:$C$3002,$J24))) | D24: =IF($J24="","",TRIM(INDEX(CLIENTES!$D$3:$D$3002,$J24)&" "&INDEX(CLIENTES!$E$3:$E$3002,$J24))) | E24: =IF($J24="","",INDEX(CLIENTES!$H$3:$H$3002,$J24)) | F24: =IF($J24="","",INDEX(CLIENTES!$K$3:$K$3002,$J24)) | G24: =IF($J24="","",INDEX(CLIENTES!$R$3:$R$3002,$J24)) | H24: =IF($J24="","",IF(N(INDEX(CLIENTES!$AF$3:$AF$3002,$J24))=0,"",INDEX(CLIENTES!$AF$3:$AF$3002,$J24))) | J24: =IFERROR(MATCH(ROW()-13,CLIENTES!$AH$3:$AH$2002,0),"")
B25: =IF($J25="","",INDEX(CLIENTES!$A$3:$A$3002,$J25)) | C25: =IF($J25="","",TRIM(INDEX(CLIENTES!$B$3:$B$3002,$J25)&" "&INDEX(CLIENTES!$C$3:$C$3002,$J25))) | D25: =IF($J25="","",TRIM(INDEX(CLIENTES!$D$3:$D$3002,$J25)&" "&INDEX(CLIENTES!$E$3:$E$3002,$J25))) | E25: =IF($J25="","",INDEX(CLIENTES!$H$3:$H$3002,$J25)) | F25: =IF($J25="","",INDEX(CLIENTES!$K$3:$K$3002,$J25)) | G25: =IF($J25="","",INDEX(CLIENTES!$R$3:$R$3002,$J25)) | H25: =IF($J25="","",IF(N(INDEX(CLIENTES!$AF$3:$AF$3002,$J25))=0,"",INDEX(CLIENTES!$AF$3:$AF$3002,$J25))) | J25: =IFERROR(MATCH(ROW()-13,CLIENTES!$AH$3:$AH$2002,0),"")
... B60: =IF($J60="","",INDEX(CLIENTES!$A$3:$A$3002,$J60)) | C60: =IF($J60="","",TRIM(INDEX(CLIENTES!$B$3:$B$3002,$J60)&" "&INDEX(CLIENTES!$C$3:$C$3002,$J60))) | D60: =IF($J60="","",TRIM(INDEX(CLIENTES!$D$3:$D$3002,$J60)&" "&INDEX(CLIENTES!$E$3:$E$3002,$J60))) | E60: =IF($J60="","",INDEX(CLIENTES!$H$3:$H$3002,$J60)) | F60: =IF($J60="","",INDEX(CLIENTES!$K$3:$K$3002,$J60)) | G60: =IF($J60="","",INDEX(CLIENTES!$R$3:$R$3002,$J60)) | H60: =IF($J60="","",IF(N(INDEX(CLIENTES!$AF$3:$AF$3002,$J60))=0,"",INDEX(CLIENTES!$AF$3:$AF$3002,$J60))) | J60: =IFERROR(MATCH(ROW()-13,CLIENTES!$AH$3:$AH$2002,0),"")

Sheet VEHICULOS
A1: FLOTA DE VEHICULOS | C1: El CODIGO se pone solo. Marca PROPIEDAD como SUBARRENDADO y anota el dueño cuando el carro no sea tuyo. | J1: ="PROPIOS: "&COUNTIF($G$3:$G$202,"PROPIO")&" carros | "&COUNTIFS(CONTRATOS!$BE$6:$BE$1005,"PROPIO",CONTRATOS!$BG$6:$BG$1005,"<>")&" contratos cerrados | cobrado "&TEXT(SUMIFS(CONTRATOS!$BT$6:$BT$1005,CONTRATOS!$BE$6:$BE$1005,"PROPIO",CONTRATOS!$BG$6:$BG$1005,"<>"),"#,##0.00")&" | utilidad "&TEXT(SUMIFS(CONTRATOS!$BW$6:$BW$1005,CONTRATOS!$BE$6:$BE$1005,"PROPIO",CONTRATOS!$BG$6:$BG$1005,"<>"),"#,##0.00")
A2: CODIGO | B2: PLACAS | C2: TIPO DE VEHICULO | D2: MARCA Y LINEA | E2: COLOR | F2: MODELO | G2: PROPIEDAD | H2: DUEÑO DEL CARRO | J2: ="SUBARRENDADOS: "&COUNTIF($G$3:$G$202,"SUBARRENDADO")&" carros | "&COUNTIFS(CONTRATOS!$BE$6:$BE$1005,"SUBARRENDADO",CONTRATOS!$BG$6:$BG$1005,"<>")&" contratos cerrados | cobrado "&TEXT(SUMIFS(CONTRATOS!$BT$6:$BT$1005,CONTRATOS!$BE$6:$BE$1005,"SUBARRENDADO",CONTRATOS!$BG$6:$BG$1005,"<>"),"#,##0.00")&" | costo de dueños "&TEXT(SUMIFS(CONTRATOS!$BV$6:$BV$1005,CONTRATOS!$BE$6:$BE$1005,"SUBARRENDADO",CONTRATOS!$BG$6:$BG$1005,"<>"),"#,##0.00")&" | utilidad "&TEXT(SUMIFS(CONTRATOS!$BW$6:$BW$1005,CONTRATOS!$BE$6:$BE$1005,"SUBARRENDADO",CONTRATOS!$BG$6:$BG$1005,"<>"),"#,##0.00")
A3: 1
A4: =A3+1
A5: =A4+1
A6: =A5+1
A7: =A6+1
A8: =A7+1
A9: =A8+1
A10: =A9+1
A11: =A10+1
A12: =A11+1
A13: =A12+1
A14: =A13+1
A15: =A14+1
... A202: =A201+1

Sheet CLIENTES
B1: 1er. | C1: 2do. | D1: 1er. | E1: 2do. | G1: FECHA | H1: CEDULA O | I1: EXTENDIDA | J1: FECHA | K1: LICENCIA | L1: LUGAR | M1: FECHA | N1: DIRECCION | S1: CORREO | T1: DIRECCION | X1: TELEFONO
A2: CODIGO | B2: APELLIDO | C2: APELLIDO | D2: NOMBRE | E2: NOMBRE | F2: NACIONALIDAD | G2: NAC. | H2: PASAPORTE | I2: EN | J2: EXPIRA | K2: CONDUCIR | L2: EMISION | M2: EXPIRA | N2: REFERENCIA | O2: MUNICIPIO | Q2: PAIS | R2: TELEFONO | S2: ELECTRONICO | T2: ADICIONAL | U2: CIUDAD | V2: ESTADO | W2: PAIS | X2: ADICIONAL | Y2: FACTURAR A | AH2: 0
A3: 1 | AF3: =IF(BUSCAR!$C$8="FECHA NAC.",$G3,IF(BUSCAR!$C$8="PASAPORTE EXPIRA",$J3,IF(BUSCAR!$C$8="LICENCIA EMISION",$L3,IF(BUSCAR!$C$8="LICENCIA EXPIRA",$M3,"")))) | AG3: =IF($B3&$C3&$D3&$E3&$H3="",0,IF(AND(OR(BUSCAR!$J$5="",ISNUMBER(SEARCH(BUSCAR!$J$5,$AI3))),OR(BUSCAR!$J$6="",ISNUMBER(SEARCH(BUSCAR!$J$6,$AI3))),OR(BUSCAR!$J$8="",ISNUMBER(SEARCH(BUSCAR!$J$8,$AI3))),OR(BUSCAR!$J$9="",ISNUMBER(SEARCH(BUSCAR!$J$9,$AI3))),OR(NOT(BUSCAR!$J$2),AND(ISNUMBER($AF3),$AF3>=BUSCAR!$J$3,$AF3<=BUSCAR!$J$4))),1,0)) | AH3: =AH2+AG3 | AI3: =IF($B3&" "&$C3&" "&$D3&" "&$E3&" "&$H3&" "&$K3&" "&$R3&" "&$AC3&" "&$AD3="","",SUBSTITUTE(SUBSTITUTE(SUBSTITUTE(SUBSTITUTE(SUBSTITUTE(SUBSTITUTE(SUBSTITUTE(UPPER($B3&" "&$C3&" "&$D3&" "&$E3&" "&$H3&" "&$K3&" "&$R3&" "&$AC3&" "&$AD3),"Á","A"),"É","E"),"Í","I"),"Ó","O"),"Ú","U"),"Ü","U"),"Ñ","N"))
A4: =A3+1 | AF4: =IF(BUSCAR!$C$8="FECHA NAC.",$G4,IF(BUSCAR!$C$8="PASAPORTE EXPIRA",$J4,IF(BUSCAR!$C$8="LICENCIA EMISION",$L4,IF(BUSCAR!$C$8="LICENCIA EXPIRA",$M4,"")))) | AG4: =IF($B4&$C4&$D4&$E4&$H4="",0,IF(AND(OR(BUSCAR!$J$5="",ISNUMBER(SEARCH(BUSCAR!$J$5,$AI4))),OR(BUSCAR!$J$6="",ISNUMBER(SEARCH(BUSCAR!$J$6,$AI4))),OR(BUSCAR!$J$8="",ISNUMBER(SEARCH(BUSCAR!$J$8,$AI4))),OR(BUSCAR!$J$9="",ISNUMBER(SEARCH(BUSCAR!$J$9,$AI4))),OR(NOT(BUSCAR!$J$2),AND(ISNUMBER($AF4),$AF4>=BUSCAR!$J$3,$AF4<=BUSCAR!$J$4))),1,0)) | AH4: =AH3+AG4 | AI4: =IF($B4&" "&$C4&" "&$D4&" "&$E4&" "&$H4&" "&$K4&" "&$R4&" "&$AC4&" "&$AD4="","",SUBSTITUTE(SUBSTITUTE(SUBSTITUTE(SUBSTITUTE(SUBSTITUTE(SUBSTITUTE(SUBSTITUTE(UPPER($B4&" "&$C4&" "&$D4&" "&$E4&" "&$H4&" "&$K4&" "&$R4&" "&$AC4&" "&$AD4),"Á","A"),"É","E"),"Í","I"),"Ó","O"),"Ú","U"),"Ü","U"),"Ñ","N"))
A5: =A4+1 | AF5: =IF(BUSCAR!$C$8="FECHA NAC.",$G5,IF(BUSCAR!$C$8="PASAPORTE EXPIRA",$J5,IF(BUSCAR!$C$8="LICENCIA EMISION",$L5,IF(BUSCAR!$C$8="LICENCIA EXPIRA",$M5,"")))) | AG5: =IF($B5&$C5&$D5&$E5&$H5="",0,IF(AND(OR(BUSCAR!$J$5="",ISNUMBER(SEARCH(BUSCAR!$J$5,$AI5))),OR(BUSCAR!$J$6="",ISNUMBER(SEARCH(BUSCAR!$J$6,$AI5))),OR(BUSCAR!$J$8="",ISNUMBER(SEARCH(BUSCAR!$J$8,$AI5))),OR(BUSCAR!$J$9="",ISNUMBER(SEARCH(BUSCAR!$J$9,$AI5))),OR(NOT(BUSCAR!$J$2),AND(ISNUMBER($AF5),$AF5>=BUSCAR!$J$3,$AF5<=BUSCAR!$J$4))),1,0)) | AH5: =AH4+AG5 | AI5: =IF($B5&" "&$C5&" "&$D5&" "&$E5&" "&$H5&" "&$K5&" "&$R5&" "&$AC5&" "&$AD5="","",SUBSTITUTE(SUBSTITUTE(SUBSTITUTE(SUBSTITUTE(SUBSTITUTE(SUBSTITUTE(SUBSTITUTE(UPPER($B5&" "&$C5&" "&$D5&" "&$E5&" "&$H5&" "&$K5&" "&$R5&" "&$AC5&" "&$AD5),"Á","A"),"É","E"),"Í","I"),"Ó","O"),"Ú","U"),"Ü","U"),"Ñ","N"))
A6: =A5+1 | AF6: =IF(BUSCAR!$C$8="FECHA NAC.",$G6,IF(BUSCAR!$C$8="PASAPORTE EXPIRA",$J6,IF(BUSCAR!$C$8="LICENCIA EMISION",$L6,IF(BUSCAR!$C$8="LICENCIA EXPIRA",$M6,"")))) | AG6: =IF($B6&$C6&$D6&$E6&$H6="",0,IF(AND(OR(BUSCAR!$J$5="",ISNUMBER(SEARCH(BUSCAR!$J$5,$AI6))),OR(BUSCAR!$J$6="",ISNUMBER(SEARCH(BUSCAR!$J$6,$AI6))),OR(BUSCAR!$J$8="",ISNUMBER(SEARCH(BUSCAR!$J$8,$AI6))),OR(BUSCAR!$J$9="",ISNUMBER(SEARCH(BUSCAR!$J$9,$AI6))),OR(NOT(BUSCAR!$J$2),AND(ISNUMBER($AF6),$AF6>=BUSCAR!$J$3,$AF6<=BUSCAR!$J$4))),1,0)) | AH6: =AH5+AG6 | AI6: =IF($B6&" "&$C6&" "&$D6&" "&$E6&" "&$H6&" "&$K6&" "&$R6&" "&$AC6&" "&$AD6="","",SUBSTITUTE(SUBSTITUTE(SUBSTITUTE(SUBSTITUTE(SUBSTITUTE(SUBSTITUTE(SUBSTITUTE(UPPER($B6&" "&$C6&" "&$D6&" "&$E6&" "&$H6&" "&$K6&" "&$R6&" "&$AC6&" "&$AD6),"Á","A"),"É","E"),"Í","I"),"Ó","O"),"Ú","U"),"Ü","U"),"Ñ","N"))
A7: =A6+1 | AF7: =IF(BUSCAR!$C$8="FECHA NAC.",$G7,IF(BUSCAR!$C$8="PASAPORTE EXPIRA",$J7,IF(BUSCAR!$C$8="LICENCIA EMISION",$L7,IF(BUSCAR!$C$8="LICENCIA EXPIRA",$M7,"")))) | AG7: =IF($B7&$C7&$D7&$E7&$H7="",0,IF(AND(OR(BUSCAR!$J$5="",ISNUMBER(SEARCH(BUSCAR!$J$5,$AI7))),OR(BUSCAR!$J$6="",ISNUMBER(SEARCH(BUSCAR!$J$6,$AI7))),OR(BUSCAR!$J$8="",ISNUMBER(SEARCH(BUSCAR!$J$8,$AI7))),OR(BUSCAR!$J$9="",ISNUMBER(SEARCH(BUSCAR!$J$9,$AI7))),OR(NOT(BUSCAR!$J$2),AND(ISNUMBER($AF7),$AF7>=BUSCAR!$J$3,$AF7<=BUSCAR!$J$4))),1,0)) | AH7: =AH6+AG7 | AI7: =IF($B7&" "&$C7&" "&$D7&" "&$E7&" "&$H7&" "&$K7&" "&$R7&" "&$AC7&" "&$AD7="","",SUBSTITUTE(SUBSTITUTE(SUBSTITUTE(SUBSTITUTE(SUBSTITUTE(SUBSTITUTE(SUBSTITUTE(UPPER($B7&" "&$C7&" "&$D7&" "&$E7&" "&$H7&" "&$K7&" "&$R7&" "&$AC7&" "&$AD7),"Á","A"),"É","E"),"Í","I"),"Ó","O"),"Ú","U"),"Ü","U"),"Ñ","N"))
A8: =A7+1 | AF8: =IF(BUSCAR!$C$8="FECHA NAC.",$G8,IF(BUSCAR!$C$8="PASAPORTE EXPIRA",$J8,IF(BUSCAR!$C$8="LICENCIA EMISION",$L8,IF(BUSCAR!$C$8="LICENCIA EXPIRA",$M8,"")))) | AG8: =IF($B8&$C8&$D8&$E8&$H8="",0,IF(AND(OR(BUSCAR!$J$5="",ISNUMBER(SEARCH(BUSCAR!$J$5,$AI8))),OR(BUSCAR!$J$6="",ISNUMBER(SEARCH(BUSCAR!$J$6,$AI8))),OR(BUSCAR!$J$8="",ISNUMBER(SEARCH(BUSCAR!$J$8,$AI8))),OR(BUSCAR!$J$9="",ISNUMBER(SEARCH(BUSCAR!$J$9,$AI8))),OR(NOT(BUSCAR!$J$2),AND(ISNUMBER($AF8),$AF8>=BUSCAR!$J$3,$AF8<=BUSCAR!$J$4))),1,0)) | AH8: =AH7+AG8 | AI8: =IF($B8&" "&$C8&" "&$D8&" "&$E8&" "&$H8&" "&$K8&" "&$R8&" "&$AC8&" "&$AD8="","",SUBSTITUTE(SUBSTITUTE(SUBSTITUTE(SUBSTITUTE(SUBSTITUTE(SUBSTITUTE(SUBSTITUTE(UPPER($B8&" "&$C8&" "&$D8&" "&$E8&" "&$H8&" "&$K8&" "&$R8&" "&$AC8&" "&$AD8),"Á","A"),"É","E"),"Í","I"),"Ó","O"),"Ú","U"),"Ü","U"),"Ñ","N"))
A9: =A8+1 | AF9: =IF(BUSCAR!$C$8="FECHA NAC.",$G9,IF(BUSCAR!$C$8="PASAPORTE EXPIRA",$J9,IF(BUSCAR!$C$8="LICENCIA EMISION",$L9,IF(BUSCAR!$C$8="LICENCIA EXPIRA",$M9,"")))) | AG9: =IF($B9&$C9&$D9&$E9&$H9="",0,IF(AND(OR(BUSCAR!$J$5="",ISNUMBER(SEARCH(BUSCAR!$J$5,$AI9))),OR(BUSCAR!$J$6="",ISNUMBER(SEARCH(BUSCAR!$J$6,$AI9))),OR(BUSCAR!$J$8="",ISNUMBER(SEARCH(BUSCAR!$J$8,$AI9))),OR(BUSCAR!$J$9="",ISNUMBER(SEARCH(BUSCAR!$J$9,$AI9))),OR(NOT(BUSCAR!$J$2),AND(ISNUMBER($AF9),$AF9>=BUSCAR!$J$3,$AF9<=BUSCAR!$J$4))),1,0)) | AH9: =AH8+AG9 | AI9: =IF($B9&" "&$C9&" "&$D9&" "&$E9&" "&$H9&" "&$K9&" "&$R9&" "&$AC9&" "&$AD9="","",SUBSTITUTE(SUBSTITUTE(SUBSTITUTE(SUBSTITUTE(SUBSTITUTE(SUBSTITUTE(SUBSTITUTE(UPPER($B9&" "&$C9&" "&$D9&" "&$E9&" "&$H9&" "&$K9&" "&$R9&" "&$AC9&" "&$AD9),"Á","A"),"É","E"),"Í","I"),"Ó","O"),"Ú","U"),"Ü","U"),"Ñ","N"))
A10: =A9+1 | AF10: =IF(BUSCAR!$C$8="FECHA NAC.",$G10,IF(BUSCAR!$C$8="PASAPORTE EXPIRA",$J10,IF(BUSCAR!$C$8="LICENCIA EMISION",$L10,IF(BUSCAR!$C$8="LICENCIA EXPIRA",$M10,"")))) | AG10: =IF($B10&$C10&$D10&$E10&$H10="",0,IF(AND(OR(BUSCAR!$J$5="",ISNUMBER(SEARCH(BUSCAR!$J$5,$AI10))),OR(BUSCAR!$J$6="",ISNUMBER(SEARCH(BUSCAR!$J$6,$AI10))),OR(BUSCAR!$J$8="",ISNUMBER(SEARCH(BUSCAR!$J$8,$AI10))),OR(BUSCAR!$J$9="",ISNUMBER(SEARCH(BUSCAR!$J$9,$AI10))),OR(NOT(BUSCAR!$J$2),AND(ISNUMBER($AF10),$AF10>=BUSCAR!$J$3,$AF10<=BUSCAR!$J$4))),1,0)) | AH10: =AH9+AG10 | AI10: =IF($B10&" "&$C10&" "&$D10&" "&$E10&" "&$H10&" "&$K10&" "&$R10&" "&$AC10&" "&$AD10="","",SUBSTITUTE(SUBSTITUTE(SUBSTITUTE(SUBSTITUTE(SUBSTITUTE(SUBSTITUTE(SUBSTITUTE(UPPER($B10&" "&$C10&" "&$D10&" "&$E10&" "&$H10&" "&$K10&" "&$R10&" "&$AC10&" "&$AD10),"Á","A"),"É","E"),"Í","I"),"Ó","O"),"Ú","U"),"Ü","U"),"Ñ","N"))
A11: =A10+1 | AF11: =IF(BUSCAR!$C$8="FECHA NAC.",$G11,IF(BUSCAR!$C$8="PASAPORTE EXPIRA",$J11,IF(BUSCAR!$C$8="LICENCIA EMISION",$L11,IF(BUSCAR!$C$8="LICENCIA EXPIRA",$M11,"")))) | AG11: =IF($B11&$C11&$D11&$E11&$H11="",0,IF(AND(OR(BUSCAR!$J$5="",ISNUMBER(SEARCH(BUSCAR!$J$5,$AI11))),OR(BUSCAR!$J$6="",ISNUMBER(SEARCH(BUSCAR!$J$6,$AI11))),OR(BUSCAR!$J$8="",ISNUMBER(SEARCH(BUSCAR!$J$8,$AI11))),OR(BUSCAR!$J$9="",ISNUMBER(SEARCH(BUSCAR!$J$9,$AI11))),OR(NOT(BUSCAR!$J$2),AND(ISNUMBER($AF11),$AF11>=BUSCAR!$J$3,$AF11<=BUSCAR!$J$4))),1,0)) | AH11: =AH10+AG11 | AI11: =IF($B11&" "&$C11&" "&$D11&" "&$E11&" "&$H11&" "&$K11&" "&$R11&" "&$AC11&" "&$AD11="","",SUBSTITUTE(SUBSTITUTE(SUBSTITUTE(SUBSTITUTE(SUBSTITUTE(SUBSTITUTE(SUBSTITUTE(UPPER($B11&" "&$C11&" "&$D11&" "&$E11&" "&$H11&" "&$K11&" "&$R11&" "&$AC11&" "&$AD11),"Á","A"),"É","E"),"Í","I"),"Ó","O"),"Ú","U"),"Ü","U"),"Ñ","N"))
A12: =A11+1 | AF12: =IF(BUSCAR!$C$8="FECHA NAC.",$G12,IF(BUSCAR!$C$8="PASAPORTE EXPIRA",$J12,IF(BUSCAR!$C$8="LICENCIA EMISION",$L12,IF(BUSCAR!$C$8="LICENCIA EXPIRA",$M12,"")))) | AG12: =IF($B12&$C12&$D12&$E12&$H12="",0,IF(AND(OR(BUSCAR!$J$5="",ISNUMBER(SEARCH(BUSCAR!$J$5,$AI12))),OR(BUSCAR!$J$6="",ISNUMBER(SEARCH(BUSCAR!$J$6,$AI12))),OR(BUSCAR!$J$8="",ISNUMBER(SEARCH(BUSCAR!$J$8,$AI12))),OR(BUSCAR!$J$9="",ISNUMBER(SEARCH(BUSCAR!$J$9,$AI12))),OR(NOT(BUSCAR!$J$2),AND(ISNUMBER($AF12),$AF12>=BUSCAR!$J$3,$AF12<=BUSCAR!$J$4))),1,0)) | AH12: =AH11+AG12 | AI12: =IF($B12&" "&$C12&" "&$D12&" "&$E12&" "&$H12&" "&$K12&" "&$R12&" "&$AC12&" "&$AD12="","",SUBSTITUTE(SUBSTITUTE(SUBSTITUTE(SUBSTITUTE(SUBSTITUTE(SUBSTITUTE(SUBSTITUTE(UPPER($B12&" "&$C12&" "&$D12&" "&$E12&" "&$H12&" "&$K12&" "&$R12&" "&$AC12&" "&$AD12),"Á","A"),"É","E"),"Í","I"),"Ó","O"),"Ú","U"),"Ü","U"),"Ñ","N"))
A13: =A12+1 | AF13: =IF(BUSCAR!$C$8="FECHA NAC.",$G13,IF(BUSCAR!$C$8="PASAPORTE EXPIRA",$J13,IF(BUSCAR!$C$8="LICENCIA EMISION",$L13,IF(BUSCAR!$C$8="LICENCIA EXPIRA",$M13,"")))) | AG13: =IF($B13&$C13&$D13&$E13&$H13="",0,IF(AND(OR(BUSCAR!$J$5="",ISNUMBER(SEARCH(BUSCAR!$J$5,$AI13))),OR(BUSCAR!$J$6="",ISNUMBER(SEARCH(BUSCAR!$J$6,$AI13))),OR(BUSCAR!$J$8="",ISNUMBER(SEARCH(BUSCAR!$J$8,$AI13))),OR(BUSCAR!$J$9="",ISNUMBER(SEARCH(BUSCAR!$J$9,$AI13))),OR(NOT(BUSCAR!$J$2),AND(ISNUMBER($AF13),$AF13>=BUSCAR!$J$3,$AF13<=BUSCAR!$J$4))),1,0)) | AH13: =AH12+AG13 | AI13: =IF($B13&" "&$C13&" "&$D13&" "&$E13&" "&$H13&" "&$K13&" "&$R13&" "&$AC13&" "&$AD13="","",SUBSTITUTE(SUBSTITUTE(SUBSTITUTE(SUBSTITUTE(SUBSTITUTE(SUBSTITUTE(SUBSTITUTE(UPPER($B13&" "&$C13&" "&$D13&" "&$E13&" "&$H13&" "&$K13&" "&$R13&" "&$AC13&" "&$AD13),"Á","A"),"É","E"),"Í","I"),"Ó","O"),"Ú","U"),"Ü","U"),"Ñ","N"))
A14: =A13+1 | AF14: =IF(BUSCAR!$C$8="FECHA NAC.",$G14,IF(BUSCAR!$C$8="PASAPORTE EXPIRA",$J14,IF(BUSCAR!$C$8="LICENCIA EMISION",$L14,IF(BUSCAR!$C$8="LICENCIA EXPIRA",$M14,"")))) | AG14: =IF($B14&$C14&$D14&$E14&$H14="",0,IF(AND(OR(BUSCAR!$J$5="",ISNUMBER(SEARCH(BUSCAR!$J$5,$AI14))),OR(BUSCAR!$J$6="",ISNUMBER(SEARCH(BUSCAR!$J$6,$AI14))),OR(BUSCAR!$J$8="",ISNUMBER(SEARCH(BUSCAR!$J$8,$AI14))),OR(BUSCAR!$J$9="",ISNUMBER(SEARCH(BUSCAR!$J$9,$AI14))),OR(NOT(BUSCAR!$J$2),AND(ISNUMBER($AF14),$AF14>=BUSCAR!$J$3,$AF14<=BUSCAR!$J$4))),1,0)) | AH14: =AH13+AG14 | AI14: =IF($B14&" "&$C14&" "&$D14&" "&$E14&" "&$H14&" "&$K14&" "&$R14&" "&$AC14&" "&$AD14="","",SUBSTITUTE(SUBSTITUTE(SUBSTITUTE(SUBSTITUTE(SUBSTITUTE(SUBSTITUTE(SUBSTITUTE(UPPER($B14&" "&$C14&" "&$D14&" "&$E14&" "&$H14&" "&$K14&" "&$R14&" "&$AC14&" "&$AD14),"Á","A"),"É","E"),"Í","I"),"Ó","O"),"Ú","U"),"Ü","U"),"Ñ","N"))
A15: =A14+1 | AF15: =IF(BUSCAR!$C$8="FECHA NAC.",$G15,IF(BUSCAR!$C$8="PASAPORTE EXPIRA",$J15,IF(BUSCAR!$C$8="LICENCIA EMISION",$L15,IF(BUSCAR!$C$8="LICENCIA EXPIRA",$M15,"")))) | AG15: =IF($B15&$C15&$D15&$E15&$H15="",0,IF(AND(OR(BUSCAR!$J$5="",ISNUMBER(SEARCH(BUSCAR!$J$5,$AI15))),OR(BUSCAR!$J$6="",ISNUMBER(SEARCH(BUSCAR!$J$6,$AI15))),OR(BUSCAR!$J$8="",ISNUMBER(SEARCH(BUSCAR!$J$8,$AI15))),OR(BUSCAR!$J$9="",ISNUMBER(SEARCH(BUSCAR!$J$9,$AI15))),OR(NOT(BUSCAR!$J$2),AND(ISNUMBER($AF15),$AF15>=BUSCAR!$J$3,$AF15<=BUSCAR!$J$4))),1,0)) | AH15: =AH14+AG15 | AI15: =IF($B15&" "&$C15&" "&$D15&" "&$E15&" "&$H15&" "&$K15&" "&$R15&" "&$AC15&" "&$AD15="","",SUBSTITUTE(SUBSTITUTE(SUBSTITUTE(SUBSTITUTE(SUBSTITUTE(SUBSTITUTE(SUBSTITUTE(UPPER($B15&" "&$C15&" "&$D15&" "&$E15&" "&$H15&" "&$K15&" "&$R15&" "&$AC15&" "&$AD15),"Á","A"),"É","E"),"Í","I"),"Ó","O"),"Ú","U"),"Ü","U"),"Ñ","N"))
... A2002: =A2001+1 | AF2002: =IF(BUSCAR!$C$8="FECHA NAC.",$G2002,IF(BUSCAR!$C$8="PASAPORTE EXPIRA",$J2002,IF(BUSCAR!$C$8="LICENCIA EMISION",$L2002,IF(BUSCAR!$C$8="LICENCIA EXPIRA",$M2002,"")))) | AG2002: =IF($B2002&$C2002&$D2002&$E2002&$H2002="",0,IF(AND(OR(BUSCAR!$J$5="",ISNUMBER(SEARCH(BUSCAR!$J$5,$AI2002))),OR(BUSCAR!$J$6="",ISNUMBER(SEARCH(BUSCAR!$J$6,$AI2002))),OR(BUSCAR!$J$8="",ISNUMBER(SEARCH(BUSCAR!$J$8,$AI2002))),OR(BUSCAR!$J$9="",ISNUMBER(SEARCH(BUSCAR!$J$9,$AI2002))),OR(NOT(BUSCAR!$J$2),AND(ISNUMBER($AF2002),$AF2002>=BUSCAR!$J$3,$AF2002<=BUSCAR!$J$4))),1,0)) | AH2002: =AH2001+AG2002 | AI2002: =IF($B2002&" "&$C2002&" "&$D2002&" "&$E2002&" "&$H2002&" "&$K2002&" "&$R2002&" "&$AC2002&" "&$AD2002="","",SUBSTITUTE(SUBSTITUTE(SUBSTITUTE(SUBSTITUTE(SUBSTITUTE(SUBSTITUTE(SUBSTITUTE(UPPER($B2002&" "&$C2002&" "&$D2002&" "&$E2002&" "&$H2002&" "&$K2002&" "&$R2002&" "&$AC2002&" "&$AD2002),"Á","A"),"É","E"),"Í","I"),"Ó","O"),"Ú","U"),"Ü","U"),"Ñ","N"))

Sheet INGRESO DE DATOS
E1: No. CONTRATO | F1: =MAX(CONTRATOS!$A$6:$A$2005)+1 | G1: FECHA | H1: =TODAY()
A3: =IFERROR(IF(VLOOKUP($C$3,CLIENTES!$A$3:$Y$6002,24,FALSE)="","",VLOOKUP($C$3,CLIENTES!$A$3:$Y$6002,24,FALSE)),"") | E3: APELLIDOS | F3: =IFERROR(IF(VLOOKUP($C$3,CLIENTES!$A$3:$Y$6002,2,FALSE)="","",VLOOKUP($C$3,CLIENTES!$A$3:$Y$6002,2,FALSE)),"") | G3: =IFERROR(IF(VLOOKUP($C$3,CLIENTES!$A$3:$Y$6002,3,FALSE)="","",VLOOKUP($C$3,CLIENTES!$A$3:$Y$6002,3,FALSE)),"")
A4: =IFERROR(IF(VLOOKUP($C$3,CLIENTES!$A$3:$Y$6002,25,FALSE)="","",VLOOKUP($C$3,CLIENTES!$A$3:$Y$6002,25,FALSE)),"") | E4: NOMBRES | F4: =IFERROR(IF(VLOOKUP($C$3,CLIENTES!$A$3:$Y$6002,4,FALSE)="","",VLOOKUP($C$3,CLIENTES!$A$3:$Y$6002,4,FALSE)),"") | G4: =IFERROR(IF(VLOOKUP($C$3,CLIENTES!$A$3:$Y$6002,5,FALSE)="","",VLOOKUP($C$3,CLIENTES!$A$3:$Y$6002,5,FALSE)),"")
A5: =IFERROR(IF(VLOOKUP($C$3,CLIENTES!$A$3:$Y$6002,26,FALSE)="","",VLOOKUP($C$3,CLIENTES!$A$3:$Y$6002,26,FALSE)),"") | E5: NACIONALIDAD | F5: =IFERROR(IF(VLOOKUP($C$3,CLIENTES!$A$3:$Y$6002,6,FALSE)="","",VLOOKUP($C$3,CLIENTES!$A$3:$Y$6002,6,FALSE)),"")
A6: =IFERROR(IF(VLOOKUP($C$3,CLIENTES!$A$3:$Y$6002,27,FALSE)="","",VLOOKUP($C$3,CLIENTES!$A$3:$Y$6002,27,FALSE)),"") | B6: TARJETA 1 | F6: =IFERROR(IF(VLOOKUP($C$3,CLIENTES!$A$3:$Y$6002,7,FALSE)="","",VLOOKUP($C$3,CLIENTES!$A$3:$Y$6002,7,FALSE)),"")
A7: =IFERROR(IF(VLOOKUP($C$3,CLIENTES!$A$3:$Y$6002,28,FALSE)="","",VLOOKUP($C$3,CLIENTES!$A$3:$Y$6002,28,FALSE)),"") | B7: VENCE | E7: DIRECCION | F7: =IFERROR(IF(VLOOKUP($C$3,CLIENTES!$A$3:$Y$6002,14,FALSE)="","",VLOOKUP($C$3,CLIENTES!$A$3:$Y$6002,14,FALSE)),"") | G7: CIUDAD
B8: AUTORIZACION 1 | F8: =IFERROR(IF(VLOOKUP($C$3,CLIENTES!$A$3:$Y$6002,18,FALSE)="","",VLOOKUP($C$3,CLIENTES!$A$3:$Y$6002,18,FALSE)),"") | G8: =IFERROR(IF(VLOOKUP($C$3,CLIENTES!$A$3:$Y$6002,15,FALSE)="","",VLOOKUP($C$3,CLIENTES!$A$3:$Y$6002,15,FALSE)),"")
A9: =IFERROR(IF(VLOOKUP($C$3,CLIENTES!$A$3:$Y$6002,19,FALSE)="","",VLOOKUP($C$3,CLIENTES!$A$3:$Y$6002,19,FALSE)),"") | B9: CODIGO CBC | F9: =IFERROR(IF(VLOOKUP($C$3,CLIENTES!$A$3:$Y$6002,8,FALSE)="","",VLOOKUP($C$3,CLIENTES!$A$3:$Y$6002,8,FALSE)),"")
A10: =IFERROR(IF(VLOOKUP($C$3,CLIENTES!$A$3:$Y$6002,20,FALSE)="","",VLOOKUP($C$3,CLIENTES!$A$3:$Y$6002,20,FALSE)),"") | B10: BANCO EMISOR | E10: MUNICIPIO | F10: =IFERROR(IF(VLOOKUP($C$3,CLIENTES!$A$3:$Y$6002,9,FALSE)="","",VLOOKUP($C$3,CLIENTES!$A$3:$Y$6002,9,FALSE)),"")
A11: =IFERROR(IF(VLOOKUP($C$3,CLIENTES!$A$3:$Y$6002,21,FALSE)="","",VLOOKUP($C$3,CLIENTES!$A$3:$Y$6002,21,FALSE)),"") | B11: TARJETA 2 | F11: =IFERROR(IF(VLOOKUP($C$3,CLIENTES!$A$3:$Y$6002,10,FALSE)="","",VLOOKUP($C$3,CLIENTES!$A$3:$Y$6002,10,FALSE)),"")
A12: =IFERROR(IF(VLOOKUP($C$3,CLIENTES!$A$3:$Y$6002,22,FALSE)="","",VLOOKUP($C$3,CLIENTES!$A$3:$Y$6002,22,FALSE)),"") | E12: LICENCIA | F12: =IFERROR(IF(VLOOKUP($C$3,CLIENTES!$A$3:$Y$6002,11,FALSE)="","",VLOOKUP($C$3,CLIENTES!$A$3:$Y$6002,11,FALSE)),"")
A13: =IFERROR(IF(VLOOKUP($C$3,CLIENTES!$A$3:$Y$6002,23,FALSE)="","",VLOOKUP($C$3,CLIENTES!$A$3:$Y$6002,23,FALSE)),"") | F13: =IFERROR(IF(VLOOKUP($C$3,CLIENTES!$A$3:$Y$6002,12,FALSE)="","",VLOOKUP($C$3,CLIENTES!$A$3:$Y$6002,12,FALSE)),"")
B14: CODIGO CBC | E14: VENCE | F14: =IFERROR(IF(VLOOKUP($C$3,CLIENTES!$A$3:$Y$6002,13,FALSE)="","",VLOOKUP($C$3,CLIENTES!$A$3:$Y$6002,13,FALSE)),"")
A15: =IFERROR(IF(VLOOKUP($C$3,CLIENTES!$A$3:$Y$6002,14,FALSE)="","",VLOOKUP($C$3,CLIENTES!$A$3:$Y$6002,14,FALSE)),"") | B15: BANCO EMISOR | E15: DIRECCION ADICIONAL | F15: =IFERROR(IF(VLOOKUP($C$3,CLIENTES!$A$3:$Y$6002,19,FALSE)="","",VLOOKUP($C$3,CLIENTES!$A$3:$Y$6002,19,FALSE)),"")
E16: CIUDAD | F16: =IFERROR(IF(VLOOKUP($C$3,CLIENTES!$A$3:$Y$6002,20,FALSE)="","",VLOOKUP($C$3,CLIENTES!$A$3:$Y$6002,20,FALSE)),"") | G16: TEL. ADICIONAL
A17: =IFERROR(IF(VLOOKUP($C$3,CLIENTES!$A$3:$Y$6002,18,FALSE)="","",VLOOKUP($C$3,CLIENTES!$A$3:$Y$6002,18,FALSE)),"") | B17: PERSONA O EMPRESA | D17: NIT | E17: ESTADO | F17: =IFERROR(IF(VLOOKUP($C$3,CLIENTES!$A$3:$Y$6002,21,FALSE)="","",VLOOKUP($C$3,CLIENTES!$A$3:$Y$6002,21,FALSE)),"") | G17: =IFERROR(IF(VLOOKUP($C$3,CLIENTES!$A$3:$Y$6002,23,FALSE)="","",VLOOKUP($C$3,CLIENTES!$A$3:$Y$6002,23,FALSE)),"")
E18: PAIS | F18: =IFERROR(IF(VLOOKUP($C$3,CLIENTES!$A$3:$Y$6002,22,FALSE)="","",VLOOKUP($C$3,CLIENTES!$A$3:$Y$6002,22,FALSE)),"")
B19: TIPO DE VEHICULO | C19: =IF(TRIM($F$19&"")<>"",IFERROR(IF(VLOOKUP($F$19,VEHICULOS!$A$3:$H$202,3,FALSE)="","",VLOOKUP($F$19,VEHICULOS!$A$3:$H$202,3,FALSE)),""),IF(TRIM($C$46&"")="","",$C$46)) | E19: CODIGO CARRO
B20: PLACAS | C20: =IF(TRIM($F$19&"")<>"",IFERROR(IF(VLOOKUP($F$19,VEHICULOS!$A$3:$H$202,2,FALSE)="","",VLOOKUP($F$19,VEHICULOS!$A$3:$H$202,2,FALSE)),""),IF(TRIM($C$45&"")="","",$C$45))
B21: MARCA Y LINEA | C21: =IF(TRIM($F$19&"")<>"",IFERROR(IF(VLOOKUP($F$19,VEHICULOS!$A$3:$H$202,4,FALSE)="","",VLOOKUP($F$19,VEHICULOS!$A$3:$H$202,4,FALSE)),""),IF(TRIM($C$47&"")="","",$C$47)) | E21: TARJETA DE CIRCULACION
B22: COLOR | C22: =IF(TRIM($F$19&"")<>"",IFERROR(IF(VLOOKUP($F$19,VEHICULOS!$A$3:$H$202,5,FALSE)="","",VLOOKUP($F$19,VEHICULOS!$A$3:$H$202,5,FALSE)),""),IF(TRIM($F$47&"")="","",$F$47)) | E22: ORIGINAL
B23: MODELO | C23: =IF(TRIM($F$19&"")<>"",IFERROR(IF(VLOOKUP($F$19,VEHICULOS!$A$3:$H$202,6,FALSE)="","",VLOOKUP($F$19,VEHICULOS!$A$3:$H$202,6,FALSE)),""),IF(TRIM($C$48&"")="","",$C$48)) | E23: AUTENTICA
B24: SEGURO TERCEROS | C24: 120
B25: SEGURO | C25: 72 | D25: NO TOCAR LO QUE ESTA EN AZUL
B26: DEDUCIBLE | C26: 55000
B27: KIL. SALIDA
B28: COMBUSTIBLE
B29: FECHA SALIDA | E29: =IF(OR(C29="",C32=""),"",C29+C32)
B30: HORA DE SALIDA | D30: HORA DE ENTRADA
B31: LUGAR SALIDA | D31: LUGAR ENTRADA
B32: DIAS A RENTAR
B33: HORA TARDIA | D33: SIN SEGURO | E33: OTROS
B34: PECIO X DIA | D34: =IF(C34="","",C34-N(C24)-N(C25)) | E34: SEGURO MENORES
B35: SEMANA | E35: CARTA PODER DESTINO
B36: MES | E36: CARTA PODER PRECIO
B37: COMBUSTIBLE A: | C37: 65 | D37: X GALON | E37: DEDUCIBLE BAJO
B38: RENTADO POR | E38: VARIOS DESCRIPCION
E39: VARIOS PRECIO
E40: SEGURO PAI
B41: NOMBRE
...

Sheet IMP. CONTRATO
A4: ACEPTO LOS CARGOS A MI TARJETA NUMERO | N4: =IF('INGRESO DE DATOS'!$C$19="","",'INGRESO DE DATOS'!$C$19)
H5: CODIGO | J5: =IF('INGRESO DE DATOS'!$C$3="","",'INGRESO DE DATOS'!$C$3)
A6: TARJETA 1 No: | D6: =IF('INGRESO DE DATOS'!$C$6="","",'INGRESO DE DATOS'!$C$6) | N6: =IF('INGRESO DE DATOS'!$C$21="","",'INGRESO DE DATOS'!$C$21)
T7: =IF('INGRESO DE DATOS'!$E$31="","",'INGRESO DE DATOS'!$E$31) | X7: =IF('INGRESO DE DATOS'!$C$29="","",'INGRESO DE DATOS'!$C$29) | Z7: =IF('INGRESO DE DATOS'!$C$30="","",'INGRESO DE DATOS'!$C$30)
A8: EXPIRA: | C8: =IF('INGRESO DE DATOS'!$C$7="","",'INGRESO DE DATOS'!$C$7) | E8: CODIGO CBC | H8: =IF('INGRESO DE DATOS'!$C$9="","",'INGRESO DE DATOS'!$C$9) | N8: =IF('INGRESO DE DATOS'!$C$20="","",'INGRESO DE DATOS'!$C$20)
A9: BANCO EMISOR | D9: =IF('INGRESO DE DATOS'!$C$10="","",'INGRESO DE DATOS'!$C$10) | T9: =IF('INGRESO DE DATOS'!$C$31="","",'INGRESO DE DATOS'!$C$31) | W9: =IF('INGRESO DE DATOS'!$E$29="","",'INGRESO DE DATOS'!$E$29) | Z9: =IF('INGRESO DE DATOS'!$C$30="","",'INGRESO DE DATOS'!$C$30)
A10: =IF('INGRESO DE DATOS'!$C$11="","",'INGRESO DE DATOS'!$C$11) | N10: =IF('INGRESO DE DATOS'!$C$22="","",'INGRESO DE DATOS'!$C$22) | V10: =IF('INGRESO DE DATOS'!$C$33="","",'INGRESO DE DATOS'!$C$33)
A11: EXPIRA: | C11: =IF('INGRESO DE DATOS'!$C$12="","",'INGRESO DE DATOS'!$C$12) | E11: CODIGO CBC | H11: =IF('INGRESO DE DATOS'!$C$14="","",'INGRESO DE DATOS'!$C$14) | N11: =IF('INGRESO DE DATOS'!$C$23="","",'INGRESO DE DATOS'!$C$23)
A13: =IF('INGRESO DE DATOS'!$D$18="","",'INGRESO DE DATOS'!$D$18) | E13: =IF('INGRESO DE DATOS'!$B$18="","",'INGRESO DE DATOS'!$B$18) | V13: =IF('INGRESO DE DATOS'!$D$34="","",'INGRESO DE DATOS'!$D$34)
O14: =IF('INGRESO DE DATOS'!$C$27="","",'INGRESO DE DATOS'!$C$27)
B15: =IF('INGRESO DE DATOS'!$F$3="","",'INGRESO DE DATOS'!$F$3)
B17: =IF('INGRESO DE DATOS'!$G$3="","",'INGRESO DE DATOS'!$G$3)
V18: 0
B19: =IF('INGRESO DE DATOS'!$F$4="","",'INGRESO DE DATOS'!$F$4)
B21: =IF('INGRESO DE DATOS'!$G$4="","",'INGRESO DE DATOS'!$G$4) | R21: =IF('INGRESO DE DATOS'!$F$35="","",'INGRESO DE DATOS'!$F$35) | W21: =IF('INGRESO DE DATOS'!$F$36="","",'INGRESO DE DATOS'!$F$36)
A23: =IF('INGRESO DE DATOS'!$F$5="","",'INGRESO DE DATOS'!$F$5) | F23: =IF('INGRESO DE DATOS'!$F$6="","",'INGRESO DE DATOS'!$F$6) | N23: =IF('INGRESO DE DATOS'!$C$28="","",'INGRESO DE DATOS'!$C$28) | V23: =IF('INGRESO DE DATOS'!$F$37="","",'INGRESO DE DATOS'!$F$37)
A25: =IF('INGRESO DE DATOS'!$F$15="","",'INGRESO DE DATOS'!$F$15) | V25: =IF('INGRESO DE DATOS'!$F$34="","",'INGRESO DE DATOS'!$F$34)
E27: =IF('INGRESO DE DATOS'!$F$17="","",'INGRESO DE DATOS'!$F$17) | I27: 0 | V27: =IF('INGRESO DE DATOS'!$C$24="","",'INGRESO DE DATOS'!$C$24)
V28: =IF('INGRESO DE DATOS'!$C$25="","",'INGRESO DE DATOS'!$C$25)
Q29: =IF('INGRESO DE DATOS'!$D$8="","",'INGRESO DE DATOS'!$D$8)
U30: =IF('INGRESO DE DATOS'!$F$40="","",'INGRESO DE DATOS'!$F$40)
A31: =IF('INGRESO DE DATOS'!$A$15="","",'INGRESO DE DATOS'!$A$15)
M32: =IF('INGRESO DE DATOS'!$C$13="","",'INGRESO DE DATOS'!$C$13) | P32: =IF('INGRESO DE DATOS'!$D$13="","",'INGRESO DE DATOS'!$D$13) | V32: =IF('INGRESO DE DATOS'!$F$38="","",'INGRESO DE DATOS'!$F$38)
A33: =IF('INGRESO DE DATOS'!$G$8="","",'INGRESO DE DATOS'!$G$8) | E33: GUATEMALA | I33: =IF('INGRESO DE DATOS'!$F$8="","",'INGRESO DE DATOS'!$F$8) | V33: =IF('INGRESO DE DATOS'!$F$39="","",'INGRESO DE DATOS'!$F$39)
V34: =IF('INGRESO DE DATOS'!$C$37="","",'INGRESO DE DATOS'!$C$37)
N35: =IF('INGRESO DE DATOS'!$C$41="","",'INGRESO DE DATOS'!$C$41)
U36: =IF('INGRESO DE DATOS'!$C$26="","",'INGRESO DE DATOS'!$C$26) | Y36: + iva
A38: =IF('INGRESO DE DATOS'!$F$9="","",'INGRESO DE DATOS'!$F$9) | H38: =IF('INGRESO DE DATOS'!$F$10="","",'INGRESO DE DATOS'!$F$10) | K38: =IF('INGRESO DE DATOS'!$F$11="","",'INGRESO DE DATOS'!$F$11)
N39: =IF('INGRESO DE DATOS'!$C$42="","",'INGRESO DE DATOS'!$C$42)
A41: =IF('INGRESO DE DATOS'!$F$12="","",'INGRESO DE DATOS'!$F$12) | H41: =IF('INGRESO DE DATOS'!$F$13="","",'INGRESO DE DATOS'!$F$13) | K41: =IF('INGRESO DE DATOS'!$F$14="","",'INGRESO DE DATOS'!$F$14)
O46: =IF('INGRESO DE DATOS'!$C$26="","",'INGRESO DE DATOS'!$C$26)
O47: =IF('INGRESO DE DATOS'!$C$25="","",'INGRESO DE DATOS'!$C$25)
T58: =IF('INGRESO DE DATOS'!$C$38="","",'INGRESO DE DATOS'!$C$38)

Sheet CONTRATOS
B1: CONTRATOS
B2: Al salir el carro: copia A5:BD5 (de No. CONTRATO hasta SUBARR. COSTO X DIA) y pega con Pegado especial > Valores en la fila indicada. Al regresar: llena las amarillas (fecha real, km de entrada, daños, combustible, descuento, % tarjeta, forma de pago). Si el carro es subarrendado, marca PAGADO AL DUEÑO cuando le pagues.
B3: ="Pega en la FILA "&(COUNT($A$6:$A$1005)+6) | G3: ="Contratos: "&COUNT($A$6:$A$1005)&" | Cobrado: "&TEXT(SUM($BT$6:$BT$1005),"#,##0.00")&" | Utilidad: "&TEXT(SUM($BW$6:$BW$1005),"#,##0.00")&" | Debes a dueños: "&TEXT(SUMIFS($BV$6:$BV$1005,$BE$6:$BE$1005,"SUBARRENDADO",$BX$6:$BX$1005,"<>SI"),"#,##0.00") | BH3: =IF($A$5="","",IF(COUNTIF($A$6:$A$1005,$A$5)>0,"El contrato "&$A$5&" ya esta archivado.",""))
A4: No. CONTRATO | B4: COD. CLIENTE | C4: CLIENTE | D4: COD. CARRO | E4: CARRO | F4: FECHA SALIDA | G4: DIAS | H4: DEVOLUCION PREVISTA | I4: KM SALIDA | J4: TARIFA X DIA | K4: RENTA | L4: DEDUCIBLE | M4: TARJETA 1 | N4: VENCE TARJETA 1 | O4: AUTORIZ. TARJETA 1 | P4: MONTO AUTORIZ. 1 | Q4: BANCO TARJETA 1 | R4: TARJETA 2 | S4: VENCE TARJETA 2 | T4: AUTORIZ. TARJETA 2 | U4: MONTO AUTORIZ. 2 | V4: BANCO TARJETA 2 | W4: PERSONA O EMPRESA | X4: NIT | Y4: T. CIRCULACION ORIGINAL | Z4: T. CIRCULACION AUTENTICA | AA4: SEGURO TERCEROS X DIA | AB4: SEGURO X DIA | AC4: COMBUSTIBLE SALIDA | AD4: HORA SALIDA | AE4: LUGAR SALIDA | AF4: HORA ENTRADA | AG4: LUGAR ENTRADA | AH4: HORA TARDIA | AI4: SEMANA | AJ4: MES | AK4: COMBUSTIBLE X GALON | AL4: RENTADO POR | AM4: SEGURO MENORES X DIA | AN4: CARTA PODER DESTINO | AO4: CARTA PODER PRECIO | AP4: DEDUCIBLE BAJO | AQ4: VARIOS DESCRIPCION | AR4: VARIOS PRECIO | AS4: SEGURO PAI X DIA | AT4: NOMBRE | AU4: LICENCIA No. | AV4: IDENTIFICACION | AW4: OBSERVACIONES | AX4: SUBARR. PLACAS | AY4: SUBARR. TIPO | AZ4: SUBARR. MARCA Y LINEA | BA4: SUBARR. COLOR | BB4: SUBARR. MODELO | BC4: SUBARR. DUEÑO | BD4: SUBARR. COSTO X DIA | BE4: PROPIEDAD | BF4: DUEÑO DEL CARRO | BG4: FECHA REAL INGRESO | BH4: KM ENTRADA | BI4: KM RECORRIDOS | BJ4: DIAS DE ATRASO | BK4: COBRO DIAS DE ATRASO | BL4: SEGUROS EXTRA | BM4: DAÑOS | BN4: CARTA PODER | BO4: COMBUSTIBLE | BP4: VARIOS | BQ4: SUBTOTAL | BR4: DESCUENTO | BS4: % TARJETA (ej: 12) | BT4: TOTAL COBRADO | BU4: COSTO SUB. X DIA | BV4: COSTO SUBARRIENDO | BW4: UTILIDAD | BX4: PAGADO AL DUEÑO | BY4: FECHA PAGO AL DUEÑO | BZ4: FORMA DE PAGO | CA4: COMENTARIOS | CB4: aux | CC4: aux | CD4: aux | CE4: aux | CF4: aux | CG4: aux
A5: =IF('INGRESO DE DATOS'!$F$1="","",'INGRESO DE DATOS'!$F$1) | B5: =IF('INGRESO DE DATOS'!$C$3="","",'INGRESO DE DATOS'!$C$3) | C5: =TRIM('INGRESO DE DATOS'!$F$3&" "&'INGRESO DE DATOS'!$G$3&" "&'INGRESO DE DATOS'!$F$4&" "&'INGRESO DE DATOS'!$G$4) | D5: =IF('INGRESO DE DATOS'!$F$19="","",'INGRESO DE DATOS'!$F$19) | E5: =TRIM('INGRESO DE DATOS'!$C$20&" "&'INGRESO DE DATOS'!$C$21) | F5: =IF('INGRESO DE DATOS'!$C$29="","",'INGRESO DE DATOS'!$C$29) | G5: =IF('INGRESO DE DATOS'!$C$32="","",'INGRESO DE DATOS'!$C$32) | H5: =IF('INGRESO DE DATOS'!$E$29="","",'INGRESO DE DATOS'!$E$29) | I5: =IF('INGRESO DE DATOS'!$C$27="","",'INGRESO DE DATOS'!$C$27) | J5: =IF('INGRESO DE DATOS'!$C$34="","",'INGRESO DE DATOS'!$C$34) | K5: =IF(OR('INGRESO DE DATOS'!$C$34="",'INGRESO DE DATOS'!$C$32=""),"",'INGRESO DE DATOS'!$C$34*'INGRESO DE DATOS'!$C$32) | L5: =IF('INGRESO DE DATOS'!$C$26="","",'INGRESO DE DATOS'!$C$26) | M5: =IF(TRIM('INGRESO DE DATOS'!$C$6&"")="","",'INGRESO DE DATOS'!$C$6) | N5: =IF(TRIM('INGRESO DE DATOS'!$C$7&"")="","",'INGRESO DE DATOS'!$C$7) | O5: =IF(TRIM('INGRESO DE DATOS'!$C$8&"")="","",'INGRESO DE DATOS'!$C$8) | P5: =IF(TRIM('INGRESO DE DATOS'!$D$8&"")="","",'INGRESO DE DATOS'!$D$8) | Q5: =IF(TRIM('INGRESO DE DATOS'!$C$10&"")="","",'INGRESO DE DATOS'!$C$10) | R5: =IF(TRIM('INGRESO DE DATOS'!$C$11&"")="","",'INGRESO DE DATOS'!$C$11) | S5: =IF(TRIM('INGRESO DE DATOS'!$C$12&"")="","",'INGRESO DE DATOS'!$C$12) | T5: =IF(TRIM('INGRESO DE DATOS'!$C$13&"")="","",'INGRESO DE DATOS'!$C$13) | U5: =IF(TRIM('INGRESO DE DATOS'!$D$13&"")="","",'INGRESO DE DATOS'!$D$13) | V5: =IF(TRIM('INGRESO DE DATOS'!$C$15&"")="","",'INGRESO DE DATOS'!$C$15) | W5: =IF(TRIM('INGRESO DE DATOS'!$B$18&"")="","",'INGRESO DE DATOS'!$B$18) | X5: =IF(TRIM('INGRESO DE DATOS'!$D$18&"")="","",'INGRESO DE DATOS'!$D$18) | Y5: =IF(TRIM('INGRESO DE DATOS'!$F$22&"")="","",'INGRESO DE DATOS'!$F$22) | Z5: =IF(TRIM('INGRESO DE DATOS'!$F$23&"")="","",'INGRESO DE DATOS'!$F$23) | AA5: =IF(TRIM('INGRESO DE DATOS'!$C$24&"")="","",'INGRESO DE DATOS'!$C$24) | AB5: =IF(TRIM('INGRESO DE DATOS'!$C$25&"")="","",'INGRESO DE DATOS'!$C$25) | AC5: =IF(TRIM('INGRESO DE DATOS'!$C$28&"")="","",'INGRESO DE DATOS'!$C$28) | AD5: =IF(TRIM('INGRESO DE DATOS'!$C$30&"")="","",'INGRESO DE DATOS'!$C$30) | AE5: =IF(TRIM('INGRESO DE DATOS'!$C$31&"")="","",'INGRESO DE DATOS'!$C$31) | AF5: =IF(TRIM('INGRESO DE DATOS'!$E$30&"")="","",'INGRESO DE DATOS'!$E$30) | AG5: =IF(TRIM('INGRESO DE DATOS'!$E$31&"")="","",'INGRESO DE DATOS'!$E$31) | AH5: =IF(TRIM('INGRESO DE DATOS'!$C$33&"")="","",'INGRESO DE DATOS'!$C$33) | AI5: =IF(TRIM('INGRESO DE DATOS'!$C$35&"")="","",'INGRESO DE DATOS'!$C$35) | AJ5: =IF(TRIM('INGRESO DE DATOS'!$C$36&"")="","",'INGRESO DE DATOS'!$C$36) | AK5: =IF(TRIM('INGRESO DE DATOS'!$C$37&"")="","",'INGRESO DE DATOS'!$C$37) | AL5: =IF(TRIM('INGRESO DE DATOS'!$C$38&"")="","",'INGRESO DE DATOS'!$C$38) | AM5: =IF(TRIM('INGRESO DE DATOS'!$F$34&"")="","",'INGRESO DE DATOS'!$F$34) | AN5: =IF(TRIM('INGRESO DE DATOS'!$F$35&"")="","",'INGRESO DE DATOS'!$F$35) | AO5: =IF(TRIM('INGRESO DE DATOS'!$F$36&"")="","",'INGRESO DE DATOS'!$F$36) | AP5: =IF(TRIM('INGRESO DE DATOS'!$F$37&"")="","",'INGRESO DE DATOS'!$F$37) | AQ5: =IF(TRIM('INGRESO DE DATOS'!$F$38&"")="","",'INGRESO DE DATOS'!$F$38) | AR5: =IF(TRIM('INGRESO DE DATOS'!$F$39&"")="","",'INGRESO DE DATOS'!$F$39) | AS5: =IF(TRIM('INGRESO DE DATOS'!$F$40&"")="","",'INGRESO DE DATOS'!$F$40) | AT5: =IF(TRIM('INGRESO DE DATOS'!$C$41&"")="","",'INGRESO DE DATOS'!$C$41) | AU5: =IF(TRIM('INGRESO DE DATOS'!$C$42&"")="","",'INGRESO DE DATOS'!$C$42) | AV5: =IF(TRIM('INGRESO DE DATOS'!$C$43&"")="","",'INGRESO DE DATOS'!$C$43) | AW5: =IF(TRIM('INGRESO DE DATOS'!$C$50&"")="","",'INGRESO DE DATOS'!$C$50) | AX5: =IF(TRIM('INGRESO DE DATOS'!$C$45&"")="","",'INGRESO DE DATOS'!$C$45) | AY5: =IF(TRIM('INGRESO DE DATOS'!$C$46&"")="","",'INGRESO DE DATOS'!$C$46) | AZ5: =IF(TRIM('INGRESO DE DATOS'!$C$47&"")="","",'INGRESO DE DATOS'!$C$47) | BA5: =IF(TRIM('INGRESO DE DATOS'!$F$47&"")="","",'INGRESO DE DATOS'!$F$47) | BB5: =IF(TRIM('INGRESO DE DATOS'!$C$48&"")="","",'INGRESO DE DATOS'!$C$48) | BC5: =IF(TRIM('INGRESO DE DATOS'!$F$45&"")="","",'INGRESO DE DATOS'!$F$45) | BD5: =IF(TRIM('INGRESO DE DATOS'!$F$46&"")="","",'INGRESO DE DATOS'!$F$46) | CC5: 0 | CE5: 0 | CG5: 0
BE6: =IF($A6="","",IF(TRIM($D6&"")="",IF(TRIM($AX6&$AY6&$AZ6&$BA6&$BB6&$BC6&$BD6&"")="","","SUBARRENDADO"),IFERROR(IF(VLOOKUP($D6,VEHICULOS!$A$3:$H$202,7,FALSE)="","",VLOOKUP($D6,VEHICULOS!$A$3:$H$202,7,FALSE)),""))) | BF6: =IF($A6="","",IF(TRIM($BC6&"")<>"",$BC6,IF(TRIM($D6&"")="","",IFERROR(IF(VLOOKUP($D6,VEHICULOS!$A$3:$H$202,8,FALSE)="","",VLOOKUP($D6,VEHICULOS!$A$3:$H$202,8,FALSE)),"")))) | BI6: =IF(OR($BH6="",$I6=""),"",$BH6-$I6) | BJ6: =IF(OR($BG6="",$H6=""),"",MAX(0,$BG6-$H6)) | BK6: =IF($A6="","",N($BJ6)*N($J6)) | BL6: =IF($A6="","",(N($AM6)+N($AS6))*(N($G6)+N($BJ6))+N($AP6)) | BN6: =IF($A6="","",N($AO6)) | BP6: =IF($A6="","",N($AR6)) | BQ6: =IF($A6="","",N($K6)+N($BK6)+N($BL6)+N($BM6)+N($BN6)+N($BO6)+N($BP6)) | BT6: =IF($A6="","",ROUND((N($BQ6)-N($BR6))*(1+N($BS6)/100),2)) | BU6: =IF($A6="","",N($BD6)) | BV6: =IF($A6="","",N($BU6)*(N($G6)+N($BJ6))) | BW6: =IF($A6="","",N($BT6)-N($BV6)) | CB6: =IF($A6="",0,IF($B6='FICHA CLIENTE'!$C$4,1,0)) | CC6: =$CC5+$CB6 | CD6: =IF($A6="",0,IF($D6='FICHA VEHICULO'!$C$4,1,0)) | CE6: =$CE5+$CD6 | CF6: =IF($A6="",0,IF($BG6="",1,0)) | CG6: =$CG5+$CF6
BE7: =IF($A7="","",IF(TRIM($D7&"")="",IF(TRIM($AX7&$AY7&$AZ7&$BA7&$BB7&$BC7&$BD7&"")="","","SUBARRENDADO"),IFERROR(IF(VLOOKUP($D7,VEHICULOS!$A$3:$H$202,7,FALSE)="","",VLOOKUP($D7,VEHICULOS!$A$3:$H$202,7,FALSE)),""))) | BF7: =IF($A7="","",IF(TRIM($BC7&"")<>"",$BC7,IF(TRIM($D7&"")="","",IFERROR(IF(VLOOKUP($D7,VEHICULOS!$A$3:$H$202,8,FALSE)="","",VLOOKUP($D7,VEHICULOS!$A$3:$H$202,8,FALSE)),"")))) | BI7: =IF(OR($BH7="",$I7=""),"",$BH7-$I7) | BJ7: =IF(OR($BG7="",$H7=""),"",MAX(0,$BG7-$H7)) | BK7: =IF($A7="","",N($BJ7)*N($J7)) | BL7: =IF($A7="","",(N($AM7)+N($AS7))*(N($G7)+N($BJ7))+N($AP7)) | BN7: =IF($A7="","",N($AO7)) | BP7: =IF($A7="","",N($AR7)) | BQ7: =IF($A7="","",N($K7)+N($BK7)+N($BL7)+N($BM7)+N($BN7)+N($BO7)+N($BP7)) | BT7: =IF($A7="","",ROUND((N($BQ7)-N($BR7))*(1+N($BS7)/100),2)) | BU7: =IF($A7="","",N($BD7)) | BV7: =IF($A7="","",N($BU7)*(N($G7)+N($BJ7))) | BW7: =IF($A7="","",N($BT7)-N($BV7)) | CB7: =IF($A7="",0,IF($B7='FICHA CLIENTE'!$C$4,1,0)) | CC7: =$CC6+$CB7 | CD7: =IF($A7="",0,IF($D7='FICHA VEHICULO'!$C$4,1,0)) | CE7: =$CE6+$CD7 | CF7: =IF($A7="",0,IF($BG7="",1,0)) | CG7: =$CG6+$CF7
BE8: =IF($A8="","",IF(TRIM($D8&"")="",IF(TRIM($AX8&$AY8&$AZ8&$BA8&$BB8&$BC8&$BD8&"")="","","SUBARRENDADO"),IFERROR(IF(VLOOKUP($D8,VEHICULOS!$A$3:$H$202,7,FALSE)="","",VLOOKUP($D8,VEHICULOS!$A$3:$H$202,7,FALSE)),""))) | BF8: =IF($A8="","",IF(TRIM($BC8&"")<>"",$BC8,IF(TRIM($D8&"")="","",IFERROR(IF(VLOOKUP($D8,VEHICULOS!$A$3:$H$202,8,FALSE)="","",VLOOKUP($D8,VEHICULOS!$A$3:$H$202,8,FALSE)),"")))) | BI8: =IF(OR($BH8="",$I8=""),"",$BH8-$I8) | BJ8: =IF(OR($BG8="",$H8=""),"",MAX(0,$BG8-$H8)) | BK8: =IF($A8="","",N($BJ8)*N($J8)) | BL8: =IF($A8="","",(N($AM8)+N($AS8))*(N($G8)+N($BJ8))+N($AP8)) | BN8: =IF($A8="","",N($AO8)) | BP8: =IF($A8="","",N($AR8)) | BQ8: =IF($A8="","",N($K8)+N($BK8)+N($BL8)+N($BM8)+N($BN8)+N($BO8)+N($BP8)) | BT8: =IF($A8="","",ROUND((N($BQ8)-N($BR8))*(1+N($BS8)/100),2)) | BU8: =IF($A8="","",N($BD8)) | BV8: =IF($A8="","",N($BU8)*(N($G8)+N($BJ8))) | BW8: =IF($A8="","",N($BT8)-N($BV8)) | CB8: =IF($A8="",0,IF($B8='FICHA CLIENTE'!$C$4,1,0)) | CC8: =$CC7+$CB8 | CD8: =IF($A8="",0,IF($D8='FICHA VEHICULO'!$C$4,1,0)) | CE8: =$CE7+$CD8 | CF8: =IF($A8="",0,IF($BG8="",1,0)) | CG8: =$CG7+$CF8
BE9: =IF($A9="","",IF(TRIM($D9&"")="",IF(TRIM($AX9&$AY9&$AZ9&$BA9&$BB9&$BC9&$BD9&"")="","","SUBARRENDADO"),IFERROR(IF(VLOOKUP($D9,VEHICULOS!$A$3:$H$202,7,FALSE)="","",VLOOKUP($D9,VEHICULOS!$A$3:$H$202,7,FALSE)),""))) | BF9: =IF($A9="","",IF(TRIM($BC9&"")<>"",$BC9,IF(TRIM($D9&"")="","",IFERROR(IF(VLOOKUP($D9,VEHICULOS!$A$3:$H$202,8,FALSE)="","",VLOOKUP($D9,VEHICULOS!$A$3:$H$202,8,FALSE)),"")))) | BI9: =IF(OR($BH9="",$I9=""),"",$BH9-$I9) | BJ9: =IF(OR($BG9="",$H9=""),"",MAX(0,$BG9-$H9)) | BK9: =IF($A9="","",N($BJ9)*N($J9)) | BL9: =IF($A9="","",(N($AM9)+N($AS9))*(N($G9)+N($BJ9))+N($AP9)) | BN9: =IF($A9="","",N($AO9)) | BP9: =IF($A9="","",N($AR9)) | BQ9: =IF($A9="","",N($K9)+N($BK9)+N($BL9)+N($BM9)+N($BN9)+N($BO9)+N($BP9)) | BT9: =IF($A9="","",ROUND((N($BQ9)-N($BR9))*(1+N($BS9)/100),2)) | BU9: =IF($A9="","",N($BD9)) | BV9: =IF($A9="","",N($BU9)*(N($G9)+N($BJ9))) | BW9: =IF($A9="","",N($BT9)-N($BV9)) | CB9: =IF($A9="",0,IF($B9='FICHA CLIENTE'!$C$4,1,0)) | CC9: =$CC8+$CB9 | CD9: =IF($A9="",0,IF($D9='FICHA VEHICULO'!$C$4,1,0)) | CE9: =$CE8+$CD9 | CF9: =IF($A9="",0,IF($BG9="",1,0)) | CG9: =$CG8+$CF9
BE10: =IF($A10="","",IF(TRIM($D10&"")="",IF(TRIM($AX10&$AY10&$AZ10&$BA10&$BB10&$BC10&$BD10&"")="","","SUBARRENDADO"),IFERROR(IF(VLOOKUP($D10,VEHICULOS!$A$3:$H$202,7,FALSE)="","",VLOOKUP($D10,VEHICULOS!$A$3:$H$202,7,FALSE)),""))) | BF10: =IF($A10="","",IF(TRIM($BC10&"")<>"",$BC10,IF(TRIM($D10&"")="","",IFERROR(IF(VLOOKUP($D10,VEHICULOS!$A$3:$H$202,8,FALSE)="","",VLOOKUP($D10,VEHICULOS!$A$3:$H$202,8,FALSE)),"")))) | BI10: =IF(OR($BH10="",$I10=""),"",$BH10-$I10) | BJ10: =IF(OR($BG10="",$H10=""),"",MAX(0,$BG10-$H10)) | BK10: =IF($A10="","",N($BJ10)*N($J10)) | BL10: =IF($A10="","",(N($AM10)+N($AS10))*(N($G10)+N($BJ10))+N($AP10)) | BN10: =IF($A10="","",N($AO10)) | BP10: =IF($A10="","",N($AR10)) | BQ10: =IF($A10="","",N($K10)+N($BK10)+N($BL10)+N($BM10)+N($BN10)+N($BO10)+N($BP10)) | BT10: =IF($A10="","",ROUND((N($BQ10)-N($BR10))*(1+N($BS10)/100),2)) | BU10: =IF($A10="","",N($BD10)) | BV10: =IF($A10="","",N($BU10)*(N($G10)+N($BJ10))) | BW10: =IF($A10="","",N($BT10)-N($BV10)) | CB10: =IF($A10="",0,IF($B10='FICHA CLIENTE'!$C$4,1,0)) | CC10: =$CC9+$CB10 | CD10: =IF($A10="",0,IF($D10='FICHA VEHICULO'!$C$4,1,0)) | CE10: =$CE9+$CD10 | CF10: =IF($A10="",0,IF($BG10="",1,0)) | CG10: =$CG9+$CF10
BE11: =IF($A11="","",IF(TRIM($D11&"")="",IF(TRIM($AX11&$AY11&$AZ11&$BA11&$BB11&$BC11&$BD11&"")="","","SUBARRENDADO"),IFERROR(IF(VLOOKUP($D11,VEHICULOS!$A$3:$H$202,7,FALSE)="","",VLOOKUP($D11,VEHICULOS!$A$3:$H$202,7,FALSE)),""))) | BF11: =IF($A11="","",IF(TRIM($BC11&"")<>"",$BC11,IF(TRIM($D11&"")="","",IFERROR(IF(VLOOKUP($D11,VEHICULOS!$A$3:$H$202,8,FALSE)="","",VLOOKUP($D11,VEHICULOS!$A$3:$H$202,8,FALSE)),"")))) | BI11: =IF(OR($BH11="",$I11=""),"",$BH11-$I11) | BJ11: =IF(OR($BG11="",$H11=""),"",MAX(0,$BG11-$H11)) | BK11: =IF($A11="","",N($BJ11)*N($J11)) | BL11: =IF($A11="","",(N($AM11)+N($AS11))*(N($G11)+N($BJ11))+N($AP11)) | BN11: =IF($A11="","",N($AO11)) | BP11: =IF($A11="","",N($AR11)) | BQ11: =IF($A11="","",N($K11)+N($BK11)+N($BL11)+N($BM11)+N($BN11)+N($BO11)+N($BP11)) | BT11: =IF($A11="","",ROUND((N($BQ11)-N($BR11))*(1+N($BS11)/100),2)) | BU11: =IF($A11="","",N($BD11)) | BV11: =IF($A11="","",N($BU11)*(N($G11)+N($BJ11))) | BW11: =IF($A11="","",N($BT11)-N($BV11)) | CB11: =IF($A11="",0,IF($B11='FICHA CLIENTE'!$C$4,1,0)) | CC11: =$CC10+$CB11 | CD11: =IF($A11="",0,IF($D11='FICHA VEHICULO'!$C$4,1,0)) | CE11: =$CE10+$CD11 | CF11: =IF($A11="",0,IF($BG11="",1,0)) | CG11: =$CG10+$CF11
BE12: =IF($A12="","",IF(TRIM($D12&"")="",IF(TRIM($AX12&$AY12&$AZ12&$BA12&$BB12&$BC12&$BD12&"")="","","SUBARRENDADO"),IFERROR(IF(VLOOKUP($D12,VEHICULOS!$A$3:$H$202,7,FALSE)="","",VLOOKUP($D12,VEHICULOS!$A$3:$H$202,7,FALSE)),""))) | BF12: =IF($A12="","",IF(TRIM($BC12&"")<>"",$BC12,IF(TRIM($D12&"")="","",IFERROR(IF(VLOOKUP($D12,VEHICULOS!$A$3:$H$202,8,FALSE)="","",VLOOKUP($D12,VEHICULOS!$A$3:$H$202,8,FALSE)),"")))) | BI12: =IF(OR($BH12="",$I12=""),"",$BH12-$I12) | BJ12: =IF(OR($BG12="",$H12=""),"",MAX(0,$BG12-$H12)) | BK12: =IF($A12="","",N($BJ12)*N($J12)) | BL12: =IF($A12="","",(N($AM12)+N($AS12))*(N($G12)+N($BJ12))+N($AP12)) | BN12: =IF($A12="","",N($AO12)) | BP12: =IF($A12="","",N($AR12)) | BQ12: =IF($A12="","",N($K12)+N($BK12)+N($BL12)+N($BM12)+N($BN12)+N($BO12)+N($BP12)) | BT12: =IF($A12="","",ROUND((N($BQ12)-N($BR12))*(1+N($BS12)/100),2)) | BU12: =IF($A12="","",N($BD12)) | BV12: =IF($A12="","",N($BU12)*(N($G12)+N($BJ12))) | BW12: =IF($A12="","",N($BT12)-N($BV12)) | CB12: =IF($A12="",0,IF($B12='FICHA CLIENTE'!$C$4,1,0)) | CC12: =$CC11+$CB12 | CD12: =IF($A12="",0,IF($D12='FICHA VEHICULO'!$C$4,1,0)) | CE12: =$CE11+$CD12 | CF12: =IF($A12="",0,IF($BG12="",1,0)) | CG12: =$CG11+$CF12
BE13: =IF($A13="","",IF(TRIM($D13&"")="",IF(TRIM($AX13&$AY13&$AZ13&$BA13&$BB13&$BC13&$BD13&"")="","","SUBARRENDADO"),IFERROR(IF(VLOOKUP($D13,VEHICULOS!$A$3:$H$202,7,FALSE)="","",VLOOKUP($D13,VEHICULOS!$A$3:$H$202,7,FALSE)),""))) | BF13: =IF($A13="","",IF(TRIM($BC13&"")<>"",$BC13,IF(TRIM($D13&"")="","",IFERROR(IF(VLOOKUP($D13,VEHICULOS!$A$3:$H$202,8,FALSE)="","",VLOOKUP($D13,VEHICULOS!$A$3:$H$202,8,FALSE)),"")))) | BI13: =IF(OR($BH13="",$I13=""),"",$BH13-$I13) | BJ13: =IF(OR($BG13="",$H13=""),"",MAX(0,$BG13-$H13)) | BK13: =IF($A13="","",N($BJ13)*N($J13)) | BL13: =IF($A13="","",(N($AM13)+N($AS13))*(N($G13)+N($BJ13))+N($AP13)) | BN13: =IF($A13="","",N($AO13)) | BP13: =IF($A13="","",N($AR13)) | BQ13: =IF($A13="","",N($K13)+N($BK13)+N($BL13)+N($BM13)+N($BN13)+N($BO13)+N($BP13)) | BT13: =IF($A13="","",ROUND((N($BQ13)-N($BR13))*(1+N($BS13)/100),2)) | BU13: =IF($A13="","",N($BD13)) | BV13: =IF($A13="","",N($BU13)*(N($G13)+N($BJ13))) | BW13: =IF($A13="","",N($BT13)-N($BV13)) | CB13: =IF($A13="",0,IF($B13='FICHA CLIENTE'!$C$4,1,0)) | CC13: =$CC12+$CB13 | CD13: =IF($A13="",0,IF($D13='FICHA VEHICULO'!$C$4,1,0)) | CE13: =$CE12+$CD13 | CF13: =IF($A13="",0,IF($BG13="",1,0)) | CG13: =$CG12+$CF13
BE14: =IF($A14="","",IF(TRIM($D14&"")="",IF(TRIM($AX14&$AY14&$AZ14&$BA14&$BB14&$BC14&$BD14&"")="","","SUBARRENDADO"),IFERROR(IF(VLOOKUP($D14,VEHICULOS!$A$3:$H$202,7,FALSE)="","",VLOOKUP($D14,VEHICULOS!$A$3:$H$202,7,FALSE)),""))) | BF14: =IF($A14="","",IF(TRIM($BC14&"")<>"",$BC14,IF(TRIM($D14&"")="","",IFERROR(IF(VLOOKUP($D14,VEHICULOS!$A$3:$H$202,8,FALSE)="","",VLOOKUP($D14,VEHICULOS!$A$3:$H$202,8,FALSE)),"")))) | BI14: =IF(OR($BH14="",$I14=""),"",$BH14-$I14) | BJ14: =IF(OR($BG14="",$H14=""),"",MAX(0,$BG14-$H14)) | BK14: =IF($A14="","",N($BJ14)*N($J14)) | BL14: =IF($A14="","",(N($AM14)+N($AS14))*(N($G14)+N($BJ14))+N($AP14)) | BN14: =IF($A14="","",N($AO14)) | BP14: =IF($A14="","",N($AR14)) | BQ14: =IF($A14="","",N($K14)+N($BK14)+N($BL14)+N($BM14)+N($BN14)+N($BO14)+N($BP14)) | BT14: =IF($A14="","",ROUND((N($BQ14)-N($BR14))*(1+N($BS14)/100),2)) | BU14: =IF($A14="","",N($BD14)) | BV14: =IF($A14="","",N($BU14)*(N($G14)+N($BJ14))) | BW14: =IF($A14="","",N($BT14)-N($BV14)) | CB14: =IF($A14="",0,IF($B14='FICHA CLIENTE'!$C$4,1,0)) | CC14: =$CC13+$CB14 | CD14: =IF($A14="",0,IF($D14='FICHA VEHICULO'!$C$4,1,0)) | CE14: =$CE13+$CD14 | CF14: =IF($A14="",0,IF($BG14="",1,0)) | CG14: =$CG13+$CF14
BE15: =IF($A15="","",IF(TRIM($D15&"")="",IF(TRIM($AX15&$AY15&$AZ15&$BA15&$BB15&$BC15&$BD15&"")="","","SUBARRENDADO"),IFERROR(IF(VLOOKUP($D15,VEHICULOS!$A$3:$H$202,7,FALSE)="","",VLOOKUP($D15,VEHICULOS!$A$3:$H$202,7,FALSE)),""))) | BF15: =IF($A15="","",IF(TRIM($BC15&"")<>"",$BC15,IF(TRIM($D15&"")="","",IFERROR(IF(VLOOKUP($D15,VEHICULOS!$A$3:$H$202,8,FALSE)="","",VLOOKUP($D15,VEHICULOS!$A$3:$H$202,8,FALSE)),"")))) | BI15: =IF(OR($BH15="",$I15=""),"",$BH15-$I15) | BJ15: =IF(OR($BG15="",$H15=""),"",MAX(0,$BG15-$H15)) | BK15: =IF($A15="","",N($BJ15)*N($J15)) | BL15: =IF($A15="","",(N($AM15)+N($AS15))*(N($G15)+N($BJ15))+N($AP15)) | BN15: =IF($A15="","",N($AO15)) | BP15: =IF($A15="","",N($AR15)) | BQ15: =IF($A15="","",N($K15)+N($BK15)+N($BL15)+N($BM15)+N($BN15)+N($BO15)+N($BP15)) | BT15: =IF($A15="","",ROUND((N($BQ15)-N($BR15))*(1+N($BS15)/100),2)) | BU15: =IF($A15="","",N($BD15)) | BV15: =IF($A15="","",N($BU15)*(N($G15)+N($BJ15))) | BW15: =IF($A15="","",N($BT15)-N($BV15)) | CB15: =IF($A15="",0,IF($B15='FICHA CLIENTE'!$C$4,1,0)) | CC15: =$CC14+$CB15 | CD15: =IF($A15="",0,IF($D15='FICHA VEHICULO'!$C$4,1,0)) | CE15: =$CE14+$CD15 | CF15: =IF($A15="",0,IF($BG15="",1,0)) | CG15: =$CG14+$CF15
BE16: =IF($A16="","",IF(TRIM($D16&"")="",IF(TRIM($AX16&$AY16&$AZ16&$BA16&$BB16&$BC16&$BD16&"")="","","SUBARRENDADO"),IFERROR(IF(VLOOKUP($D16,VEHICULOS!$A$3:$H$202,7,FALSE)="","",VLOOKUP($D16,VEHICULOS!$A$3:$H$202,7,FALSE)),""))) | BF16: =IF($A16="","",IF(TRIM($BC16&"")<>"",$BC16,IF(TRIM($D16&"")="","",IFERROR(IF(VLOOKUP($D16,VEHICULOS!$A$3:$H$202,8,FALSE)="","",VLOOKUP($D16,VEHICULOS!$A$3:$H$202,8,FALSE)),"")))) | BI16: =IF(OR($BH16="",$I16=""),"",$BH16-$I16) | BJ16: =IF(OR($BG16="",$H16=""),"",MAX(0,$BG16-$H16)) | BK16: =IF($A16="","",N($BJ16)*N($J16)) | BL16: =IF($A16="","",(N($AM16)+N($AS16))*(N($G16)+N($BJ16))+N($AP16)) | BN16: =IF($A16="","",N($AO16)) | BP16: =IF($A16="","",N($AR16)) | BQ16: =IF($A16="","",N($K16)+N($BK16)+N($BL16)+N($BM16)+N($BN16)+N($BO16)+N($BP16)) | BT16: =IF($A16="","",ROUND((N($BQ16)-N($BR16))*(1+N($BS16)/100),2)) | BU16: =IF($A16="","",N($BD16)) | BV16: =IF($A16="","",N($BU16)*(N($G16)+N($BJ16))) | BW16: =IF($A16="","",N($BT16)-N($BV16)) | CB16: =IF($A16="",0,IF($B16='FICHA CLIENTE'!$C$4,1,0)) | CC16: =$CC15+$CB16 | CD16: =IF($A16="",0,IF($D16='FICHA VEHICULO'!$C$4,1,0)) | CE16: =$CE15+$CD16 | CF16: =IF($A16="",0,IF($BG16="",1,0)) | CG16: =$CG15+$CF16
BE17: =IF($A17="","",IF(TRIM($D17&"")="",IF(TRIM($AX17&$AY17&$AZ17&$BA17&$BB17&$BC17&$BD17&"")="","","SUBARRENDADO"),IFERROR(IF(VLOOKUP($D17,VEHICULOS!$A$3:$H$202,7,FALSE)="","",VLOOKUP($D17,VEHICULOS!$A$3:$H$202,7,FALSE)),""))) | BF17: =IF($A17="","",IF(TRIM($BC17&"")<>"",$BC17,IF(TRIM($D17&"")="","",IFERROR(IF(VLOOKUP($D17,VEHICULOS!$A$3:$H$202,8,FALSE)="","",VLOOKUP($D17,VEHICULOS!$A$3:$H$202,8,FALSE)),"")))) | BI17: =IF(OR($BH17="",$I17=""),"",$BH17-$I17) | BJ17: =IF(OR($BG17="",$H17=""),"",MAX(0,$BG17-$H17)) | BK17: =IF($A17="","",N($BJ17)*N($J17)) | BL17: =IF($A17="","",(N($AM17)+N($AS17))*(N($G17)+N($BJ17))+N($AP17)) | BN17: =IF($A17="","",N($AO17)) | BP17: =IF($A17="","",N($AR17)) | BQ17: =IF($A17="","",N($K17)+N($BK17)+N($BL17)+N($BM17)+N($BN17)+N($BO17)+N($BP17)) | BT17: =IF($A17="","",ROUND((N($BQ17)-N($BR17))*(1+N($BS17)/100),2)) | BU17: =IF($A17="","",N($BD17)) | BV17: =IF($A17="","",N($BU17)*(N($G17)+N($BJ17))) | BW17: =IF($A17="","",N($BT17)-N($BV17)) | CB17: =IF($A17="",0,IF($B17='FICHA CLIENTE'!$C$4,1,0)) | CC17: =$CC16+$CB17 | CD17: =IF($A17="",0,IF($D17='FICHA VEHICULO'!$C$4,1,0)) | CE17: =$CE16+$CD17 | CF17: =IF($A17="",0,IF($BG17="",1,0)) | CG17: =$CG16+$CF17
... BE1005: =IF($A1005="","",IF(TRIM($D1005&"")="",IF(TRIM($AX1005&$AY1005&$AZ1005&$BA1005&$BB1005&$BC1005&$BD1005&"")="","","SUBARRENDADO"),IFERROR(IF(VLOOKUP($D1005,VEHICULOS!$A$3:$H$202,7,FALSE)="","",VLOOKUP($D1005,VEHICULOS!$A$3:$H$202,7,FALSE)),""))) | BF1005: =IF($A1005="","",IF(TRIM($BC1005&"")<>"",$BC1005,IF(TRIM($D1005&"")="","",IFERROR(IF(VLOOKUP($D1005,VEHICULOS!$A$3:$H$202,8,FALSE)="","",VLOOKUP($D1005,VEHICULOS!$A$3:$H$202,8,FALSE)),"")))) | BI1005: =IF(OR($BH1005="",$I1005=""),"",$BH1005-$I1005) | BJ1005: =IF(OR($BG1005="",$H1005=""),"",MAX(0,$BG1005-$H1005)) | BK1005: =IF($A1005="","",N($BJ1005)*N($J1005)) | BL1005: =IF($A1005="","",(N($AM1005)+N($AS1005))*(N($G1005)+N($BJ1005))+N($AP1005)) | BN1005: =IF($A1005="","",N($AO1005)) | BP1005: =IF($A1005="","",N($AR1005)) | BQ1005: =IF($A1005="","",N($K1005)+N($BK1005)+N($BL1005)+N($BM1005)+N($BN1005)+N($BO1005)+N($BP1005)) | BT1005: =IF($A1005="","",ROUND((N($BQ1005)-N($BR1005))*(1+N($BS1005)/100),2)) | BU1005: =IF($A1005="","",N($BD1005)) | BV1005: =IF($A1005="","",N($BU1005)*(N($G1005)+N($BJ1005))) | BW1005: =IF($A1005="","",N($BT1005)-N($BV1005)) | CB1005: =IF($A1005="",0,IF($B1005='FICHA CLIENTE'!$C$4,1,0)) | CC1005: =$CC1004+$CB1005 | CD1005: =IF($A1005="",0,IF($D1005='FICHA VEHICULO'!$C$4,1,0)) | CE1005: =$CE1004+$CD1005 | CF1005: =IF($A1005="",0,IF($BG1005="",1,0)) | CG1005: =$CG1004+$CF1005

Sheet CIERRE
B2: CIERRE DE CONTRATO | E2: Para imprimir este cierre: hoja IMP. CIERRE DE CONTRATO | J2: =IFERROR(MATCH($C$4,CONTRATOS!$A$6:$A$1005,0),"") | K2: =TODAY()
B4: No. de contrato: | E4: =IF($C$4="","",IF($J$2="","Ese numero de contrato no esta en la bitacora.","Esta en la FILA "&($J$2+5)&" de CONTRATOS"))
B6: CLIENTE | C6: =IF($J$2="","",IF(INDEX(CONTRATOS!$C$6:$C$1005,$J$2)="","",INDEX(CONTRATOS!$C$6:$C$1005,$J$2)))
B7: CARRO | C7: =IF($J$2="","",IF(INDEX(CONTRATOS!$E$6:$E$1005,$J$2)="","",INDEX(CONTRATOS!$E$6:$E$1005,$J$2)))
B8: PROPIEDAD | C8: =IF($J$2="","",IF(INDEX(CONTRATOS!$BE$6:$BE$1005,$J$2)="","",INDEX(CONTRATOS!$BE$6:$BE$1005,$J$2))) | E8: DUEÑO | F8: =IF($J$2="","",IF(INDEX(CONTRATOS!$BF$6:$BF$1005,$J$2)="","",INDEX(CONTRATOS!$BF$6:$BF$1005,$J$2)))
B10: FECHA SALIDA | C10: =IF($J$2="","",IF(INDEX(CONTRATOS!$F$6:$F$1005,$J$2)="","",INDEX(CONTRATOS!$F$6:$F$1005,$J$2))) | E10: KM SALIDA | F10: =IF($J$2="","",IF(INDEX(CONTRATOS!$I$6:$I$1005,$J$2)="","",INDEX(CONTRATOS!$I$6:$I$1005,$J$2)))
B11: DEVOLUCION PREVISTA | C11: =IF($J$2="","",IF(INDEX(CONTRATOS!$H$6:$H$1005,$J$2)="","",INDEX(CONTRATOS!$H$6:$H$1005,$J$2))) | E11: KM ENTRADA | F11: =IF($J$2="","",IF(INDEX(CONTRATOS!$BH$6:$BH$1005,$J$2)="","",INDEX(CONTRATOS!$BH$6:$BH$1005,$J$2)))
B12: FECHA REAL INGRESO | C12: =IF($J$2="","",IF(INDEX(CONTRATOS!$BG$6:$BG$1005,$J$2)="","",INDEX(CONTRATOS!$BG$6:$BG$1005,$J$2))) | E12: KM RECORRIDOS | F12: =IF($J$2="","",IF(INDEX(CONTRATOS!$BI$6:$BI$1005,$J$2)="","",INDEX(CONTRATOS!$BI$6:$BI$1005,$J$2)))
B13: DIAS DE ATRASO | C13: =IF($J$2="","",IF(INDEX(CONTRATOS!$BJ$6:$BJ$1005,$J$2)="","",INDEX(CONTRATOS!$BJ$6:$BJ$1005,$J$2))) | E13: DIAS CONTRATADOS | F13: =IF($J$2="","",IF(INDEX(CONTRATOS!$G$6:$G$1005,$J$2)="","",INDEX(CONTRATOS!$G$6:$G$1005,$J$2)))
B16: DETALLE DEL COBRO
B17: RENTA | C17: =IF($J$2="","",IF(INDEX(CONTRATOS!$K$6:$K$1005,$J$2)="","",INDEX(CONTRATOS!$K$6:$K$1005,$J$2)))
B18: COBRO DIAS DE ATRASO | C18: =IF($J$2="","",IF(INDEX(CONTRATOS!$BK$6:$BK$1005,$J$2)="","",INDEX(CONTRATOS!$BK$6:$BK$1005,$J$2)))
B19: SEGUROS EXTRA (menores, PAI, deducible bajo) | C19: =IF($J$2="","",IF(INDEX(CONTRATOS!$BL$6:$BL$1005,$J$2)="","",INDEX(CONTRATOS!$BL$6:$BL$1005,$J$2)))
B20: DAÑOS | C20: =IF($J$2="","",IF(INDEX(CONTRATOS!$BM$6:$BM$1005,$J$2)="","",INDEX(CONTRATOS!$BM$6:$BM$1005,$J$2)))
B21: CARTA PODER | C21: =IF($J$2="","",IF(INDEX(CONTRATOS!$BN$6:$BN$1005,$J$2)="","",INDEX(CONTRATOS!$BN$6:$BN$1005,$J$2)))
B22: COMBUSTIBLE | C22: =IF($J$2="","",IF(INDEX(CONTRATOS!$BO$6:$BO$1005,$J$2)="","",INDEX(CONTRATOS!$BO$6:$BO$1005,$J$2)))
B23: VARIOS | C23: =IF($J$2="","",IF(INDEX(CONTRATOS!$BP$6:$BP$1005,$J$2)="","",INDEX(CONTRATOS!$BP$6:$BP$1005,$J$2)))
B24: SUBTOTAL | C24: =IF($J$2="","",IF(INDEX(CONTRATOS!$BQ$6:$BQ$1005,$J$2)="","",INDEX(CONTRATOS!$BQ$6:$BQ$1005,$J$2)))
B25: ( - ) DESCUENTO | C25: =IF($J$2="","",IF(INDEX(CONTRATOS!$BR$6:$BR$1005,$J$2)="","",INDEX(CONTRATOS!$BR$6:$BR$1005,$J$2)))
B26: % TARJETA | C26: =IF($J$2="","",IF(INDEX(CONTRATOS!$BS$6:$BS$1005,$J$2)="","",INDEX(CONTRATOS!$BS$6:$BS$1005,$J$2)))
B27: TOTAL A COBRAR | C27: =IF($J$2="","",IF(INDEX(CONTRATOS!$BT$6:$BT$1005,$J$2)="","",INDEX(CONTRATOS!$BT$6:$BT$1005,$J$2)))
B28: COSTO SUBARRIENDO X DIA | C28: =IF($J$2="","",IF(INDEX(CONTRATOS!$BU$6:$BU$1005,$J$2)="","",INDEX(CONTRATOS!$BU$6:$BU$1005,$J$2)))
B29: ( - ) COSTO SUBARRIENDO TOTAL | C29: =IF($J$2="","",IF(INDEX(CONTRATOS!$BV$6:$BV$1005,$J$2)="","",INDEX(CONTRATOS!$BV$6:$BV$1005,$J$2)))
B30: UTILIDAD | C30: =IF($J$2="","",IF(INDEX(CONTRATOS!$BW$6:$BW$1005,$J$2)="","",INDEX(CONTRATOS!$BW$6:$BW$1005,$J$2)))
B31: PAGO AL DUEÑO | C31: =IF($J$2="","",IF(INDEX(CONTRATOS!$BE$6:$BE$1005,$J$2)<>"SUBARRENDADO","No aplica (carro propio)",IF(INDEX(CONTRATOS!$BX$6:$BX$1005,$J$2)="SI","PAGADO"&IF(INDEX(CONTRATOS!$BY$6:$BY$1005,$J$2)="",""," el "&TEXT(INDEX(CONTRATOS!$BY$6:$BY$1005,$J$2),"dd/mm/yyyy")),"PENDIENTE: Q "&TEXT(INDEX(CONTRATOS!$BV$6:$BV$1005,$J$2),"#,##0.00"))))
B32: FORMA DE PAGO | C32: =IF($J$2="","",IF(INDEX(CONTRATOS!$BZ$6:$BZ$1005,$J$2)="","",INDEX(CONTRATOS!$BZ$6:$BZ$1005,$J$2)))
B33: COMENTARIOS | C33: =IF($J$2="","",IF(INDEX(CONTRATOS!$CA$6:$CA$1005,$J$2)="","",INDEX(CONTRATOS!$CA$6:$CA$1005,$J$2)))
B35: CONTRATOS ABIERTOS | E35: ="Carros afuera ahorita: "&MAX(CONTRATOS!$CG$6:$CG$1005)&" (un contrato queda abierto mientras no tenga FECHA REAL INGRESO)"
B36: No. | C36: CLIENTE | D36: CARRO | E36: SALIDA | F36: DEVOLUCION PREVISTA | G36: DIAS DE ATRASO
